Workbook

Sheet x
B4: Veste | D4: Stear
B5: Manteau | D5: Sweet
B6: Robe | D6: Mango
B7: Masque | D7: Luso
B8: Chemise | D8: Imprima
B9: Pantalon
B10: Mono
B11: Bermuda
B12: Top
B13: Gilet
B14: Short

Sheet FF
B1: LA FICHE DE PRODUCTION DES CHAÎNES E06.03C | AA1: =+AD1/AC1 -> 0.79144367 | AC1: =+SUBTOTAL(9,AC4:AC194) -> 248790 | AD1: =+SUBTOTAL(9,AD4:AD194) -> 196903.27
B2: CODERSA s.a.r.l | R2: Sortie Chaine | W2: =+SUMIF(J4:J1000,R2,W4:W1000) -> 26422 | X2: DATE : | Z2: 44032
B3: CH | C3: IMPORT | D3: CLIENT | E3: MODELE | F3: DESIG | G3: Meth | I3: Réel | K3: 01 | L3: 02 | M3: 03 | N3: 04 | O3: 05 | P3: 06 | Q3: 07 | R3: 08 | S3: 09 | T3: 10 | U3: 11 | V3: Moy | W3: Total | X3: Cumul | Z3: Encours | AA3: R%
B4: =+B5 -> 1 | G4: VT | H4: P/H | I4: P/H | J4: Entre Chaine | R4: 156 | W4: =+SUM(K4:U4) -> 156 | X4: =+Y4+W4 -> 832 | Y4: 676
B5: 1 | C5: 101-20 | D5: LUSO | E5: 4043-263-063 | F5: Gilet | G5: 42.5 | H5: 60 | I5: 56 | J5: Sortie Chaine | K5: 0 | L5: 0 | M5: 20 | N5: 20 | O5: 25 | P5: 25 | Q5: 30 | R5: 30 | V5: =+IF(COUNTA(K5:U5)=0,0,W5/COUNTA(K5:U5)) -> 18.75 | W5: =+SUM(K5:U5) -> 150 | X5: =+W5+Y5 -> 150 | Y5: 0 | Z5: =+X4-X5 -> 682 | AA5: =+IF(((W6+(W7/2))*60)=0,"",(G5*W5)/((W6+(W7/2))*60)) -> 0.32003012 | AD5: =+W5*G5 -> 6375
B6: =+B5 -> 1 | H6: EFF | I6: EFF | J6: Effectifs | K6: 40 | L6: 40 | M6: 40 | N6: 40 | O6: 40 | P6: 40 | Q6: 40 | R6: 40 | W6: =+SUM(K6:U6) -> 320 | AC6: =+W6*60 -> 19200
B7: =+B5 -> 1 | H7: 46 | I7: 41.5 | J7: Stagiaire | K7: 3 | L7: 3 | M7: 3 | N7: 3 | O7: 3 | P7: 3 | Q7: 3 | R7: 3 | W7: =+SUM(K7:U7) -> 24 | Z7: =+Z5/(I5*8) -> 1.5223214 | AC7: =+W7*30 -> 720
B8: =+B9 -> 2 | G8: VT | H8: P/H | I8: P/H | J8: Entre Chaine | K8: 42 | L8: 42 | M8: 100 | N8: 21 | R8: 0 | W8: =+SUM(K8:U8) -> 205 | X8: =+Y8+W8 -> 3753 | Y8: 3548
B9: 2 | C9: 089-20 | D9: Stear | E9: 8029-743-999 | F9: Robe | G9: 41.37 | H9: 68 | I9: 53 | J9: Sortie Chaine | K9: 35 | L9: 65 | M9: 65 | V9: =+IF(COUNTA(K9:U9)=0,0,W9/COUNTA(K9:U9)) -> 55 | W9: =+SUM(K9:U9) -> 165 | X9: =+W9+Y9 -> 2207 | Y9: 2042 | Z9: =+X8-X9 -> 1546 | AA9: =+IF(((W10+(W11/2))*60)=0,"",(G9*W9)/((W10+(W11/2))*60)) -> 0.96823404 | AD9: =+W9*G9 -> 6826.05
B10: =+B9 -> 2 | H10: EFF | I10: EFF | J10: Effectifs | K10: 36 | L10: 40 | M10: 40 | W10: =+SUM(K10:U10) -> 116 | AC10: =+W10*60 -> 6960
B11: =+B9 -> 2 | H11: 52 | I11: 40.5 | J11: Stagiaire | K11: 1 | L11: 1 | M11: 1 | W11: =+SUM(K11:U11) -> 3 | Z11: =+Z9/(I9*8) -> 3.6462264 | AC11: =+W11*30 -> 90
B12: =+B13 -> 3 | G12: VT | H12: P/H | I12: P/H | J12: Entre Chaine | R12: 282 | W12: =+SUM(K12:U12) -> 282 | X12: =+Y12+W12 -> 13786 | Y12: 13504
B13: 3 | C13: 037-20 | D13: LUSO | E13: 4043-100-093 | F13: Veste | G13: 49.99 | H13: 50 | I13: 50 | J13: Sortie Chaine | K13: 50 | L13: 50 | M13: 50 | N13: 50 | O13: 50 | P13: 50 | Q13: 50 | R13: 58 | V13: =+IF(COUNTA(K13:U13)=0,0,W13/COUNTA(K13:U13)) -> 51 | W13: =+SUM(K13:U13) -> 408 | X13: =+W13+Y13 -> 12752 | Y13: 12344 | Z13: =+X12-X13 -> 1034 | AA13: =+IF(((W14+(W15/2))*60)=0,"",(G13*W13)/((W14+(W15/2))*60)) -> 0.91873514 | AD13: =+W13*G13 -> 20395.92
B14: =+B13 -> 3 | H14: EFF | I14: EFF | J14: Effectifs | K14: 42 | L14: 44 | M14: 44 | N14: 44 | O14: 45 | P14: 45 | Q14: 45 | R14: 45 | W14: =+SUM(K14:U14) -> 354 | AC14: =+W14*60 -> 21240
B15: =+B13 -> 3 | H15: 46 | I15: 46 | J15: Stagiaire | K15: 4 | L15: 4 | M15: 4 | N15: 4 | O15: 4 | P15: 4 | Q15: 4 | R15: 4 | W15: =+SUM(K15:U15) -> 32 | Z15: =+Z13/(I13*8) -> 2.585 | AC15: =+W15*30 -> 960
B16: =+B17 -> 3 | G16: VT | H16: P/H | I16: P/H | J16: Entre Chaine | R16: 126 | W16: =+SUM(K16:U16) -> 126 | X16: 126 | Y16: 13504
B17: 3 | C17: 037-20 | D17: LUSO | E17: 4043-800-063 | F17: Veste | J17: Sortie Chaine | V17: =+IF(COUNTA(K17:U17)=0,0,W17/COUNTA(K17:U17)) -> 0 | W17: =+SUM(K17:U17) -> 0 | Y17: 12344 | Z17: =+X16-X17 -> 126 | AA17: =+IF(((W18+(W19/2))*60)=0,"",(G17*W17)/((W18+(W19/2))*60)) | AD17: =+W17*G17 -> 0
B18: =+B17 -> 3 | H18: EFF | I18: EFF | J18: Effectifs | W18: =+SUM(K18:U18) -> 0 | AC18: =+W18*60 -> 0
B19: =+B17 -> 3 | J19: Stagiaire | W19: =+SUM(K19:U19) -> 0 | Z19: =+Z17/(I17*8) -> #DIV/0! | AC19: =+W19*30 -> 0
B20: =+B21 -> 4 | G20: VT | H20: P/H | I20: P/H | J20: Entre Chaine | W20: =+SUM(K20:U20) -> 0 | X20: 1580 | Y20: 1325
B21: 4 | C21: 074-20 | D21: Imprima | E21: ZALI01 LOUP CHINE | F21: Manteau | G21: 51.86 | H21: 60 | I21: 35 | J21: Sortie Chaine | K21: 40 | L21: 20 | M21: 10 | V21: =+IF(COUNTA(K21:U21)=0,0,W21/COUNTA(K21:U21)) -> 23.333333 | W21: =+SUM(K21:U21) -> 70 | X21: =972+W21 -> 1042 | Y21: 659 | Z21: =+X20-X21 -> 538 | AA21: =+IF(((W22+(W23/2))*60)=0,"",(G21*W21)/((W22+(W23/2))*60)) -> 0.50843137 | AD21: =+W21*G21 -> 3630.2
B22: =+B21 -> 4 | H22: EFF | I22: EFF | J22: Effectifs | K22: 39 | L22: 38 | M22: 36 | W22: =+SUM(K22:U22) -> 113 | AC22: =+W22*60 -> 6780
B23: =+B21 -> 4 | H23: 52 | I23: 47 | J23: Stagiaire | K23: 4 | L23: 4 | M23: 4 | W23: =+SUM(K23:U23) -> 12 | Z23: =+Z21/(I21*8) -> 1.9214286 | AC23: =+W23*30 -> 360
B24: =+B25 -> 4 | G24: VT | H24: P/H | I24: P/H | J24: Entre Chaine | K24: 30 | L24: 30 | M24: 30 | N24: 30 | W24: =+SUM(K24:U24) -> 120 | X24: 90 | Y24: 1325
B25: 4 | C25: 105-20 | D25: Mango | E25: 701366 will | F25: Manteau | I25: 40 | J25: Sortie Chaine | V25: =+IF(COUNTA(K25:U25)=0,0,W25/COUNTA(K25:U25)) -> 0 | W25: =+SUM(K25:U25) -> 0 | Y25: 659 | Z25: =+X24-X25 -> 90 | AA25: =+IF(((W26+(W27/2))*60)=0,"",(G25*W25)/((W26+(W27/2))*60)) -> 0 | AD25: =+W25*G25 -> 0
B26: =+B25 -> 4 | H26: EFF | I26: EFF | J26: Effectifs | K26: 6 | L26: 7 | M26: 9 | W26: =+SUM(K26:U26) -> 22 | AC26: =+W26*60 -> 1320
B27: =+B25 -> 4 | J27: Stagiaire | W27: =+SUM(K27:U27) -> 0 | Z27: =+Z25/(I25*8) -> 0.28125 | AC27: =+W27*30 -> 0
B28: =+B29 -> 6 | G28: VT | H28: P/H | I28: P/H | J28: Entre Chaine | K28: 75 | L28: 75 | M28: 75 | N28: 75 | W28: =+SUM(K28:U28) -> 300 | X28: =+Y28+W28 -> 5050 | Y28: 4750
B29: 6 | C29: 071-20 | D29: LUSO | E29: 4043-257-721 | F29: Veste | G29: 43.38 | H29: 62 | I29: 58 | J29: Sortie Chaine | K29: 58 | L29: 58 | M29: 50 | V29: =+IF(COUNTA(K29:U29)=0,0,W29/COUNTA(K29:U29)) -> 55.333333 | W29: =+SUM(K29:U29) -> 166 | X29: =+W29+Y29 -> 4451 | Y29: 4285 | Z29: =+X28-X29 -> 599 | AA29: =+IF(((W30+(W31/2))*60)=0,"",(G29*W29)/((W30+(W31/2))*60)) -> 0.87285818 | AD29: =+W29*G29 -> 7201.08
B30: =+B29 -> 6 | H30: EFF | I30: EFF | J30: Effectifs | K30: 43 | L30: 45 | M30: 45 | W30: =+SUM(K30:U30) -> 133 | AC30: =+W30*60 -> 7980
B31: =+B29 -> 6 | H31: 50 | I31: 46.5 | J31: Stagiaire | K31: 3 | L31: 3 | M31: 3 | W31: =+SUM(K31:U31) -> 9 | Z31: =+Z29/(I29*8) -> 1.2909483 | AC31: =+W31*30 -> 270
B32: =+B33 -> 7 | G32: VT | H32: P/H | I32: P/H | J32: Entre Chaine | R32: 500 | W32: =+SUM(K32:U32) -> 500 | X32: =+Y32+W32 -> 2900 | Y32: 2400
B33: 7 | C33: 093-20 | D33: Stear | E33: 8168-289-069 | F33: Robe | G33: 38 | H33: 65 | I33: 62 | J33: Sortie Chaine | K33: 40 | L33: 60 | M33: 60 | N33: 60 | O33: 26 | P33: 60 | Q33: 60 | R33: 60 | V33: =+IF(COUNTA(K33:U33)=0,0,W33/COUNTA(K33:U33)) -> 53.25 | W33: =+SUM(K33:U33) -> 426 | X33: =+W33+Y33 -> 1906 | Y33: 1480 | Z33: =+X32-X33 -> 994 | AA33: =+IF(((W34+(W35/2))*60)=0,"",(G33*W33)/((W34+(W35/2))*60)) -> 0.74019204 | AD33: =+W33*G33 -> 16188
B34: =+B33 -> 7 | H34: EFF | I34: EFF | J34: Effectifs | K34: 39 | L34: 42 | M34: 42 | N34: 46 | O34: 46 | P34: 46 | Q34: 46 | R34: 46 | W34: =+SUM(K34:U34) -> 353 | AC34: =+W34*60 -> 21180
B35: =+B33 -> 7 | H35: 46 | I35: 43.5 | J35: Stagiaire | K35: 2 | L35: 3 | M35: 3 | N35: 3 | O35: 3 | P35: 3 | Q35: 3 | R35: 3 | W35: =+SUM(K35:U35) -> 23 | Z35: =+Z33/(I33*8) -> 2.0040323 | AC35: =+W35*30 -> 690
B36: =+B37 -> 8 | G36: VT | H36: P/H | I36: P/H | J36: Entre Chaine | K36: 1450 | L36: 1450 | M36: 1450 | N36: 2175 | W36: =+SUM(K36:U36) -> 6525 | X36: =+Y36+W36 -> 37761 | Y36: 31236
B37: 8 | D37: Sweet | E37: Masque | F37: Masque | G37: 2.53 | I37: 1089 | J37: Sortie Chaine | K37: 1050 | L37: 1100 | M37: 1100 | V37: =+IF(COUNTA(K37:U37)=0,0,W37/COUNTA(K37:U37)) -> 1083.3333 | W37: =+SUM(K37:U37) -> 3250 | X37: =+W37+Y37 -> 26540 | Y37: 23290 | Z37: =+X36-X37 -> 11221 | AA37: =+IF(((W38+(W39/2))*60)=0,"",(G37*W37)/((W38+(W39/2))*60)) -> 0.90756071 | AD37: =+W37*G37 -> 8222.5
B38: =+B37 -> 8 | H38: EFF | I38: EFF | J38: Effectifs | K38: 48 | L38: 50 | M38: 50 | W38: =+SUM(K38:U38) -> 148 | AC38: =+W38*60 -> 8880
B39: =+B37 -> 8 | I39: 51 | J39: Stagiaire | K39: 2 | L39: 2 | M39: 2 | W39: =+SUM(K39:U39) -> 6 | Z39: =+Z37/(I37*8) -> 1.2879936 | AC39: =+W39*30 -> 180
B40: =+B41 -> 9 | G40: VT | H40: P/H | I40: P/H | J40: Entre Chaine | R40: 7645 | W40: =+SUM(K40:U40) -> 7645 | X40: =+Y40+W40 -> 24183 | Y40: 16538
...

Sheet 02-04-2022
B1: LA FICHE DE PRODUCTION DES CHAÎNES E06.03C | AB1: EXL 009-20
A2: 77 | AB2: =+AF2/AE2 -> 3.6857333 | AE2: =+SUBTOTAL(9,AE6:AE103) -> 7200 | AF2: =+SUBTOTAL(9,AF6:AF103) -> 26537.28
J3: HEURES SAISIE | L3: 7:10 | M3: 8:10 | N3: 9:10 | O3: 10:10 | P3: 11:25 | Q3: 12:25 | R3: 13:25 | S3: 14:25 | T3: 15:00
B4: CODERSA S.A.R.L. | J4: Fin Heure | L4: 6:45 | M4: 7:45 | N4: 8:45 | O4: 9:45 | P4: 11:00 | Q4: 12:00 | R4: 13:00 | S4: 14:00 | T4: 15:00 | W4: Sortie Chaine | Y4: =+X87 -> 538 | Z4: DATE : | AB4: 44653 | AD4: =+SUM(AD6:AD91) -> 120
B5: CH | C5: IMPORT | E5: CLIENT | F5: MODELE | G5: QTE PREVU | H5: DESIG | I5: METHODES | L5: 1 | M5: 2 | N5: 3 | O5: 4 | P5: 5 | Q5: 6 | R5: 7 | S5: 8 | T5: 9 | U5: 10 | V5: 11 | W5: Moy | X5: H.Lancement | Y5: Total | Z5: Cumul | AB5: Encours | AC5: R%
B6: =+B7 -> 1 | I6: VT | J6: P/H | K6: Entre Chaine | X6: =+W8 -> -53 | Y6: =+SUM(L6:V6) -> 0 | Z6: =+AA6+Y6 -> 3954 | AA6: 3954
B7: 1 | C7: 029-22 | E7: Stear | F7: 2198-799-712 | G7: 5038 | H7: Veste | I7: 58.92 | J7: 53 | K7: Sortie Chaine | W7: =+IF(COUNTA(L7:V7)=8,Y7/(COUNTA(L7:V7)-0.5),IF(COUNTA(L7:V7)=0,0,Y7/COUNTA(L7:V7))) -> 0 | Y7: =+SUM(L7:V7) -> 0 | Z7: =+Y7+AA7 -> 3126 | AA7: 3126 | AB7: =+Z6-Z7 -> 828 | AC7: =+IF(((Y8+(Y9/2))*60)=0,"",(I7*Y7)/((Y8+(Y9/2))*60)) | AF7: =+Y7*I7 -> 0
B8: =B7 -> 1 | D8: =+B7 -> 1 | F8: =+VLOOKUP(F7,'Obj Prix'!$H:$H,2,FALSE) -> #N/A | I8: 1 | J8: EFF | K8: Effectifs | W8: =+W7-J7 -> -53 | Y8: =+SUM(L8:V8)-S8/2 -> 0
B9: =B7 -> 1 | C9: HICHAM | D9: =+D8+100 -> 101 | F9: REDOUANE | H9: 2 PàM+4FL+Ctr | I9: =+IF(J9="","",IF(J7=0,"",(J7*I7)/(J9*60))) -> 0.91308772 | J9: 57 | K9: Stagiaire | X9: 7.85 | Y9: =+SUM(L9:V9)-S9/2 -> 0 | AB9: =+IFERROR(AB7/(J7*9),"") -> 1.7358491 | AD9: =+Y8+Y9/2 -> 0 | AE9: =+AD9*60 -> 0 | AG9: =+IF((Y7-J7*9)>=0,"",Y7-J7*9) -> -477
B10: =+B11 -> 2 | I10: VT | J10: P/H | K10: Entre Chaine | X10: =+W12 -> -55 | Y10: =+SUM(L10:V10) -> 0 | Z10: =+AA10+Y10 -> 9370 | AA10: 9370 | AE10: =+AD10*60 -> 0
B11: 2 | C11: 026-22 | E11: Denllo | F11: 2890-878-800 | G11: 9000 | H11: Gilet | I11: 51.85 | J11: 55 | K11: Sortie Chaine | W11: =+IF(COUNTA(L11:V11)=8,Y11/(COUNTA(L11:V11)-0.5),IF(COUNTA(L11:V11)=0,0,Y11/COUNTA(L11:V11))) -> 0 | Y11: =+SUM(L11:V11) -> 0 | Z11: =+Y11+AA11 -> 8462 | AA11: 8462 | AB11: =+Z10-Z11 -> 908 | AC11: =+IF(((Y12+(Y13/2))*60)=0,"",(I11*Y11)/((Y12+(Y13/2))*60)) | AE11: =+AD11*60 -> 0 | AF11: =+Y11*I11 -> 0
B12: =+B11 -> 2 | D12: =+B11 -> 2 | F12: =+VLOOKUP(F11,'Obj Prix'!$H:$H,2,FALSE) -> #N/A | J12: EFF | K12: Effectifs | W12: =+W11-J11 -> -55 | Y12: =+SUM(L12:V12)-S12/2 -> 0 | AE12: =+AD12*60 -> 0
B13: =+B11 -> 2 | C13: JAMAL | D13: =+D12+100 -> 102 | F13: REDOUANE | I13: =+IF(J13="","",IF(J11=0,"",(J11*I11)/(J13*60))) -> 0.91402244 | J13: 52 | K13: Stagiaire | X13: 6.39 | Y13: =+SUM(L13:V13)-S13/2 -> 0 | AB13: =+IFERROR(AB11/(J11*9),"") -> 1.8343434 | AD13: =+Y12+Y13/2 -> 0 | AE13: =+AD13*60 -> 0 | AG13: =+IF((Y11-J11*9)>=0,"",Y11-J11*9) -> -495
B14: =+B15 -> 3 | I14: VT | J14: P/H | K14: Entre Chaine | X14: =+W16 -> -53 | Y14: =+SUM(L14:V14) -> 0 | Z14: =+AA14+Y14 -> 4818 | AA14: 4818 | AE14: =+AD14*60 -> 0
B15: 3 | C15: 029-22 | E15: Stear | F15: 2198-799-712 | G15: 5038 | H15: Veste | I15: 58.92 | J15: 53 | K15: Sortie Chaine | W15: =+IF(COUNTA(L15:V15)=8,Y15/(COUNTA(L15:V15)-0.5),IF(COUNTA(L15:V15)=0,0,Y15/COUNTA(L15:V15))) -> 0 | Y15: =+SUM(L15:V15) -> 0 | Z15: =+Y15+AA15 -> 3982 | AA15: 3982 | AB15: =+Z14-Z15 -> 836 | AC15: =+IF(((Y16+(Y17/2))*60)=0,"",(I15*Y15)/((Y16+(Y17/2))*60)) | AE15: =+AD15*60 -> 0 | AF15: =+Y15*I15 -> 0
B16: =+B15 -> 3 | D16: =+B15 -> 3 | F16: =+VLOOKUP(F15,'Obj Prix'!$H:$H,2,FALSE) -> #N/A | I16: 1 | J16: EFF | K16: Effectifs | W16: =+W15-J15 -> -53 | Y16: =+SUM(L16:V16)-S16/2 -> 0 | AE16: =+AD16*60 -> 0
B17: =+B15 -> 3 | C17: KHALID | D17: =+D16+100 -> 103 | F17: REDOUANE | H17: 2 PàM+4FL+Ctr | I17: =+IF(J17="","",IF(J15=0,"",(J15*I15)/(J17*60))) -> 0.88213559 | J17: 59 | K17: Stagiaire | X17: 25.71 | Y17: =+SUM(L17:V17)-S17/2 -> 0 | AB17: =+IFERROR(AB15/(J15*9),"") -> 1.7526205 | AD17: =+Y16+Y17/2 -> 0 | AE17: =+AD17*60 -> 0 | AG17: =+IF((Y15-J15*9)>=0,"",Y15-J15*9) -> -477
B18: =+B19 -> 4 | I18: VT | J18: P/H | K18: Entre Chaine | X18: =+W20 -> -53 | Y18: =+SUM(L18:V18) -> 0 | Z18: =+AA18+Y18 -> 4381 | AA18: 4381 | AE18: =+AD18*60 -> 0
B19: 4 | C19: 029-22 | E19: Stear | F19: 2198-799-712 | G19: 5038 | H19: Veste | I19: 58.92 | J19: 53 | K19: Sortie Chaine | W19: =+IF(COUNTA(L19:V19)=8,Y19/(COUNTA(L19:V19)-0.5),IF(COUNTA(L19:V19)=0,0,Y19/COUNTA(L19:V19))) -> 0 | Y19: =+SUM(L19:V19) -> 0 | Z19: =+Y19+AA19 -> 3425 | AA19: 3425 | AB19: =+Z18-Z19 -> 956 | AC19: =+IF(((Y20+(Y21/2))*60)=0,"",(I19*Y19)/((Y20+(Y21/2))*60)) | AE19: =+AD19*60 -> 0 | AF19: =+Y19*I19 -> 0
B20: =+B19 -> 4 | C20: HAMID | D20: =+B19 -> 4 | F20: =+VLOOKUP(F19,'Obj Prix'!$H:$H,2,FALSE) -> #N/A | I20: 1 | J20: EFF | K20: Effectifs | W20: =+W19-J19 -> -53 | Y20: =+SUM(L20:V20)-S20/2 -> 0 | AE20: =+AD20*60 -> 0
B21: =+B19 -> 4 | D21: =+D20+100 -> 104 | F21: REDOUANE | H21: 2 PàM+4FL+Ctr | I21: =+IF(J21="","",IF(J19=0,"",(J19*I19)/(J21*60))) -> 0.88213559 | J21: 59 | K21: Stagiaire | X21: 32.67 | Y21: =+SUM(L21:V21)-S21/2 -> 0 | AB21: =+IFERROR(AB19/(J19*9),"") -> 2.0041929 | AD21: =+Y20+Y21/2 -> 0 | AE21: =+AD21*60 -> 0 | AG21: =+IF((Y19-J19*9)>=0,"",Y19-J19*9) -> -477
B22: =+B23 -> 5 | I22: VT | J22: P/H | K22: Entre Chaine | X22: =+W24 -> -50 | Y22: =+SUM(L22:V22) -> 0 | Z22: =+AA22+Y22 -> 4861 | AA22: 4861 | AE22: =+AD22*60 -> 0
B23: 5 | C23: 022-22 | E23: Denllo | F23: 3177-707-712 | G23: 5500 | H23: Veste | I23: 62.7 | J23: 50 | K23: Sortie Chaine | W23: =+IF(COUNTA(L23:V23)=8,Y23/(COUNTA(L23:V23)-0.5),IF(COUNTA(L23:V23)=0,0,Y23/COUNTA(L23:V23))) -> 0 | Y23: =+SUM(L23:V23) -> 0 | Z23: =+Y23+AA23 -> 4080 | AA23: 4080 | AB23: =+Z22-Z23 -> 781 | AC23: =+IF(((Y24+(Y25/2))*60)=0,"",(I23*Y23)/((Y24+(Y25/2))*60)) | AE23: =+AD23*60 -> 0 | AF23: =+Y23*I23 -> 0
B24: =+B23 -> 5 | D24: =+B23 -> 5 | F24: =+VLOOKUP(F23,'Obj Prix'!$H:$H,2,FALSE) -> #N/A | I24: 1 | J24: EFF | K24: Effectifs | W24: =+W23-J23 -> -50 | Y24: =+SUM(L24:V24)-S24/2 -> 0 | AE24: =+AD24*60 -> 0
B25: =+B23 -> 5 | C25: MOHAMMED | D25: =+D24+100 -> 105 | F25: TOURABI | H25: 2 PàM+1F | I25: =+IF(J25="","",IF(J23=0,"",(J23*I23)/(J25*60))) -> 0.90086207 | J25: 58 | K25: Stagiaire | X25: 11 | Y25: =+SUM(L25:V25)-S25/2 -> 0 | AB25: =+IFERROR(AB23/(J23*9),"") -> 1.7355556 | AD25: =+Y24+Y25/2 -> 0 | AE25: =+AD25*60 -> 0 | AG25: =+IF((Y23-J23*9)>=0,"",Y23-J23*9) -> -450
B26: =+B27 -> 7 | I26: VT | J26: P/H | K26: Entre Chaine | X26: =+W28 -> -50 | Y26: =+SUM(L26:V26) -> 0 | Z26: =+AA26+Y26 -> 5548 | AA26: 5548 | AE26: =+AD26*60 -> 0
B27: 7 | C27: 022-22 | E27: Denllo | F27: 3177-707-712 | G27: 5500 | H27: Veste | I27: 62.7 | J27: 50 | K27: Sortie Chaine | W27: =+IF(COUNTA(L27:V27)=8,Y27/(COUNTA(L27:V27)-0.5),IF(COUNTA(L27:V27)=0,0,Y27/COUNTA(L27:V27))) -> 0 | Y27: =+SUM(L27:V27) -> 0 | Z27: =+Y27+AA27 -> 4976 | AA27: 4976 | AB27: =+Z26-Z27 -> 572 | AC27: =+IF(((Y28+(Y29/2))*60)=0,"",(I27*Y27)/((Y28+(Y29/2))*60)) | AE27: =+AD27*60 -> 0 | AF27: =+Y27*I27 -> 0
B28: =+B27 -> 7 | D28: =+B27 -> 7 | F28: =+VLOOKUP(F27,'Obj Prix'!$H:$H,2,FALSE) -> #N/A | H28: 1 | I28: 3 | J28: EFF | K28: Effectifs | W28: =+W27-J27 -> -50 | Y28: =+SUM(L28:V28)-S28/2 -> 0 | AE28: =+AD28*60 -> 0
B29: =+B27 -> 7 | C29: YOUSSEF | D29: =+D28+100 -> 107 | F29: TOURABI | H29: 5 PAM 1fer+ 1 ct | I29: =+IF(J29="","",IF(J27=0,"",(J27*I27)/(J29*60))) -> 0.90086207 | J29: 58 | K29: Stagiaire | X29: 12.91 | Y29: =+SUM(L29:V29)-S29/2 -> 0 | AB29: =+IFERROR(AB27/(J27*9),"") -> 1.2711111 | AD29: =+Y28+Y29/2 -> 0 | AE29: =+AD29*60 -> 0 | AG29: =+IF((Y27-J27*9)>=0,"",Y27-J27*9) -> -450
B30: =+B31 -> 7 | I30: VT | J30: P/H | K30: Entre Chaine | X30: =+W32 -> 0 | Y30: =+SUM(L30:V30) -> 0 | Z30: =+AA30+Y30 -> 100 | AA30: 100 | AE30: =+AD30*60 -> 0
B31: 7 | C31: 039-22 | E31: sweet | F31: 221404197 | H31: chemise | K31: Sortie Chaine | W31: =+IF(COUNTA(L31:V31)=8,Y31/(COUNTA(L31:V31)-0.5),IF(COUNTA(L31:V31)=0,0,Y31/COUNTA(L31:V31))) -> 0 | Y31: =+SUM(L31:V31) -> 0 | Z31: =+Y31+AA31 -> 0 | AA31: 0 | AB31: =+Z30-Z31 -> 100 | AC31: =+IF(((Y32+(Y33/2))*60)=0,"",(I31*Y31)/((Y32+(Y33/2))*60)) | AE31: =+AD31*60 -> 0 | AF31: =+Y31*I31 -> 0
B32: =+B31 -> 7 | D32: =+B31 -> 7 | F32: =+VLOOKUP(F31,'Obj Prix'!$H:$H,2,FALSE) -> #N/A | J32: EFF | K32: Effectifs | W32: =+W31-J31 -> 0 | Y32: =+SUM(L32:V32)-S32/2 -> 0 | AE32: =+AD32*60 -> 0
B33: =+B31 -> 7 | C33: YOUSSEF | D33: =+D32+100 -> 107 | F33: TOURABI | H33: 5 PAM 1fer+ 1 ct | I33: =+IF(J33="","",IF(J31=0,"",(J31*I31)/(J33*60))) | J33: 58 | K33: Stagiaire | X33: =+(COUNTA(L31:V31)-(Y31/J31)) -> #DIV/0! | Y33: =+SUM(L33:V33)-S33/2 -> 0 | AB33: =+IFERROR(AB31/(J31*9),"") | AD33: =+Y32+Y33/2 -> 0 | AE33: =+AD33*60 -> 0 | AG33: =+IF((Y31-J31*9)>=0,"",Y31-J31*9)
B34: =+B35 -> 8 | I34: VT | J34: P/H | K34: Entre Chaine | X34: =+W36 -> -55 | Y34: =+SUM(L34:V34) -> 0 | Z34: =+AA34+Y34 -> 10253 | AA34: 10253 | AE34: =+AD34*60 -> 0
B35: 8 | C35: 020-22 | E35: Stear | F35: 2218-232-251 | G35: 7500 | H35: Veste | I35: 54.22 | J35: 55 | K35: Sortie Chaine | W35: =+IF(COUNTA(L35:V35)=8,Y35/(COUNTA(L35:V35)-0.5),IF(COUNTA(L35:V35)=0,0,Y35/COUNTA(L35:V35))) -> 0 | Y35: =+SUM(L35:V35) -> 0 | Z35: =+Y35+AA35 -> 9903 | AA35: 9903 | AB35: =+Z34-Z35 -> 350 | AC35: =+IF(((Y36+(Y37/2))*60)=0,"",(I35*Y35)/((Y36+(Y37/2))*60)) | AE35: =+AD35*60 -> 0 | AF35: =+Y35*I35 -> 0
B36: =+B35 -> 8 | D36: =+B35 -> 8 | F36: =+VLOOKUP(F35,'Obj Prix'!$H:$H,2,FALSE) -> #N/A | H36: 1 | I36: 2 | J36: EFF | K36: Effectifs | W36: =+W35-J35 -> -55 | Y36: =+SUM(L36:V36)-S36/2 -> 0 | AE36: =+AD36*60 -> 0
B37: =+B35 -> 8 | C37: OTMAN | D37: =+D36+100 -> 108 | F37: AMINE | I37: =+IF(J37="","",IF(J35=0,"",(J35*I35)/(J37*60))) -> 0.90366667 | J37: 55 | K37: Stagiaire | X37: 8.09 | Y37: =+SUM(L37:V37)-S37/2 -> 0 | AB37: =+IFERROR(AB35/(J35*9),"") -> 0.70707071 | AD37: =+Y36+Y37/2 -> 0 | AE37: =+AD37*60 -> 0 | AG37: =+IF((Y35-J35*9)>=0,"",Y35-J35*9) -> -495
B38: =+B39 -> 9 | I38: VT | J38: P/H | K38: Entre Chaine | X38: =+W40 -> -53 | Y38: =+SUM(L38:V38) -> 0 | Z38: =+AA38+Y38 -> 4621 | AA38: 4621 | AE38: =+AD38*60 -> 0
B39: 9 | C39: 029-22 | E39: Stear | F39: 2198-799-712 | G39: 5038 | H39: Veste | I39: 61.42 | J39: 53 | K39: Sortie Chaine | W39: =+IF(COUNTA(L39:V39)=8,Y39/(COUNTA(L39:V39)-0.5),IF(COUNTA(L39:V39)=0,0,Y39/COUNTA(L39:V39))) -> 0 | Y39: =+SUM(L39:V39) -> 0 | Z39: =+Y39+AA39 -> 3611 | AA39: 3611 | AB39: =+Z38-Z39 -> 1010 | AC39: =+IF(((Y40+(Y41/2))*60)=0,"",(I39*Y39)/((Y40+(Y41/2))*60)) | AE39: =+AD39*60 -> 0 | AF39: =+Y39*I39 -> 0
B40: =+B39 -> 9 | F40: =+VLOOKUP(F39,'Obj Prix'!$H:$H,2,FALSE) -> #N/A | H40: 1 | I40: 2 | J40: EFF | K40: Effectifs | W40: =+W39-J39 -> -53 | Y40: =+SUM(L40:V40)-S40/2 -> 0 | AE40: =+AD40*60 -> 0
...

Sheet 25-04-2022 (Simulation)
B1: LA FICHE DE PRODUCTION DES CHAÎNES E06.03C | AB1: EXL 009-20
A2: 77 | AB2: =+AF2/AE2 -> 0.8871642 | AE2: =+SUBTOTAL(9,AE6:AE115) -> 433380 | AF2: =+SUBTOTAL(9,AF6:AF115) -> 384479.22
J3: HEURES SAISIE | L3: 5:45 | M3: 6:45 | N3: 7:45 | O3: 8:45 | P3: 10:00 | Q3: 11:00 | R3: 12:00 | S3: 12:45
B4: CODERSA S.A.R.L. | J4: Fin Heure | L4: 5:30 | M4: 6:30 | N4: 7:30 | O4: 8:30 | P4: 9:45 | Q4: 10:45 | R4: 11:45 | S4: 12:45 | W4: Sortie Chaine | Y4: =+X99 -> 8219 | Z4: DATE : | AB4: 44676 | AD4: =+SUM(AD6:AD103) -> 7223
B5: CH | C5: IMPORT | E5: CLIENT | F5: MODELE | G5: QTE PREVU | H5: DESIG | I5: METHODES | L5: 1 | M5: 2 | N5: 3 | O5: 4 | P5: 5 | Q5: 6 | R5: 7 | S5: 8 | T5: 9 | U5: 10 | V5: 11 | W5: Moy | X5: H.Lancement | Y5: Total | Z5: Cumul | AB5: Encours | AC5: R%
B6: =+B7 -> 1 | I6: VT | J6: P/H | K6: Entre Chaine | L6: 40 | M6: 50 | N6: 37 | O6: 37 | P6: 40 | Q6: 37 | R6: 40 | X6: =+W8 -> -13.125 | Y6: =+SUM(L6:V6) -> 281 | Z6: =+AA6+Y6 -> 1225 | AA6: 944
B7: 1 | C7: 074-22 | E7: ZARA-MAN | F7: 340-400-800 | H7: Veste | I7: 72.32 | J7: 40 | K7: Sortie Chaine | L7: 25 | M7: 18 | N7: 20 | O7: 22 | P7: 30 | Q7: 30 | R7: 35 | S7: 35 | W7: =+IF(COUNTA(L7:V7)=0,0,Y7/(COUNTA(L7:V7))) -> 26.875 | Y7: =+SUM(L7:V7) -> 215 | Z7: =+Y7+AA7 -> 423 | AA7: 208 | AB7: =+Z6-Z7 -> 802 | AC7: =+IF(((Y8+(Y9/2))*60)=0,"",(I7*Y7)/((Y8+(Y9/2))*60)) -> 0.62899676 | AF7: =+Y7*I7 -> 15548.8
B8: =B7 -> 1 | D8: =+B7 -> 1 | F8: =+VLOOKUP(F7,'Obj Prix'!$H:$H,2,FALSE) -> #N/A | J8: EFF | K8: Effectifs | L8: 49 | M8: 49 | N8: 49 | O8: 49 | P8: 49 | Q8: 49 | R8: 49 | S8: 49 | W8: =+W7-J7 -> -13.125 | Y8: =+SUM(L8:V8) -> 392
B9: =B7 -> 1 | C9: HICHAM | D9: =+D8+100 -> 101 | F9: AMINE | H9: 1 MS | I9: =+IF(J9="","",IF(J7=0,"",(J7*I7)/(J9*60))) -> 0.89283951 | J9: 54 | K9: Stagiaire | L9: 5 | M9: 5 | N9: 5 | O9: 5 | P9: 5 | Q9: 5 | R9: 5 | S9: 5 | X9: =16.8+(COUNTA(L7:V7)-(Y7/J7)) -> 19.425 | Y9: =+SUM(L9:V9) -> 40 | AB9: =+IFERROR(AB7/(J7*9),"") -> 2.2277778 | AD9: =+Y8+Y9/2 -> 412 | AE9: =+AD9*60 -> 24720 | AG9: =+IF((Y7-J7*9)>=0,"",Y7-J7*9) -> -145
B10: =+B11 -> 2 | I10: VT | J10: P/H | K10: Entre Chaine | L10: 60 | M10: 60 | N10: 60 | O10: 60 | P10: 60 | Q10: 60 | R10: 60 | X10: =+W12 -> 0 | Y10: =+SUM(L10:V10) -> 420 | Z10: =+AA10+Y10 -> 5121 | AA10: 4701 | AE10: =+AD10*60 -> 0
B11: 2 | C11: 036-22 | E11: Stear | F11: 3362-696-727 | G11: 5599 | H11: Gabardina | I11: 52.67 | J11: 50 | K11: Sortie Chaine | L11: 40 | M11: 30 | N11: 55 | O11: 60 | P11: 27 | Q11: 70 | R11: 60 | S11: 58 | W11: =+IF(COUNTA(L11:V11)=0,0,Y11/(COUNTA(L11:V11))) -> 50 | Y11: =+SUM(L11:V11) -> 400 | Z11: =+Y11+AA11 -> 4399 | AA11: 3999 | AB11: =+Z10-Z11 -> 722 | AC11: =+IF(((Y12+(Y13/2))*60)=0,"",(I11*Y11)/((Y12+(Y13/2))*60)) -> 0.91440972 | AE11: =+AD11*60 -> 0 | AF11: =+Y11*I11 -> 21068
B12: =+B11 -> 2 | D12: =+B11 -> 2 | F12: =+VLOOKUP(F11,'Obj Prix'!$H:$H,2,FALSE) -> #N/A | J12: EFF | K12: Effectifs | L12: 48 | M12: 48 | N12: 48 | O12: 48 | P12: 48 | Q12: 48 | R12: 48 | S12: 48 | W12: =+W11-J11 -> 0 | Y12: =+SUM(L12:V12) -> 384 | AE12: =+AD12*60 -> 0
B13: =+B11 -> 2 | C13: JAMAL | D13: =+D12+100 -> 102 | F13: REDOUANE | I13: =+IF(J13="","",IF(J11=0,"",(J11*I11)/(J13*60))) -> 0.87783333 | J13: 50 | K13: Stagiaire | X13: 40.56 | Y13: =+SUM(L13:V13) -> 0 | AB13: =+IFERROR(AB11/(J11*9),"") -> 1.6044444 | AD13: =+Y12+Y13/2 -> 384 | AE13: =+AD13*60 -> 23040 | AG13: =+IF((Y11-J11*9)>=0,"",Y11-J11*9) -> -50
B14: =+B15 -> 3 | I14: VT | J14: P/H | K14: Entre Chaine | L14: 100 | M14: 50 | N14: 50 | O14: 50 | P14: 50 | Q14: 50 | R14: 50 | S14: 50 | X14: =+W16 -> 0 | Y14: =+SUM(L14:V14) -> 450 | Z14: =+AA14+Y14 -> 2822 | AA14: 2372 | AE14: =+AD14*60 -> 0
B15: 3 | C15: 064-22 | E15: Stear | F15: 8035-888-800 | G15: 6600 | H15: Veste | I15: 51.08 | J15: 55 | K15: Sortie Chaine | L15: 55 | M15: 50 | N15: 55 | O15: 55 | P15: 55 | Q15: 55 | R15: 55 | S15: 60 | W15: =+IF(COUNTA(L15:V15)=0,0,Y15/(COUNTA(L15:V15))) -> 55 | Y15: =+SUM(L15:V15) -> 440 | Z15: =+Y15+AA15 -> 1949 | AA15: 1509 | AB15: =+Z14-Z15 -> 873 | AC15: =+IF(((Y16+(Y17/2))*60)=0,"",(I15*Y15)/((Y16+(Y17/2))*60)) -> 0.95557823 | AE15: =+AD15*60 -> 0 | AF15: =+Y15*I15 -> 22475.2
B16: =+B15 -> 3 | D16: =+B15 -> 3 | F16: =+VLOOKUP(F15,'Obj Prix'!$H:$H,2,FALSE) -> #N/A | J16: EFF | K16: Effectifs | L16: 48 | M16: 48 | N16: 48 | O16: 48 | P16: 48 | Q16: 48 | R16: 48 | S16: 48 | W16: =+W15-J15 -> 0 | Y16: =+SUM(L16:V16) -> 384 | AE16: =+AD16*60 -> 0
B17: =+B15 -> 3 | C17: KHALID | D17: =+D16+100 -> 103 | F17: TOURABI | I17: =+IF(J17="","",IF(J15=0,"",(J15*I15)/(J17*60))) -> 0.90044872 | J17: 52 | K17: Stagiaire | L17: 2 | M17: 2 | N17: 2 | O17: 2 | P17: 2 | Q17: 2 | R17: 2 | S17: 2 | X17: =11.59+(COUNTA(L15:V15)-(Y15/J15)) -> 11.59 | Y17: =+SUM(L17:V17) -> 16 | AB17: =+IFERROR(AB15/(J15*9),"") -> 1.7636364 | AD17: =+Y16+Y17/2 -> 392 | AE17: =+AD17*60 -> 23520 | AG17: =+IF((Y15-J15*9)>=0,"",Y15-J15*9) -> -55
B18: =+B19 -> 4 | I18: VT | J18: P/H | K18: Entre Chaine | L18: 50 | M18: 50 | N18: 50 | O18: 100 | P18: 100 | Q18: 50 | R18: 50 | X18: =+W20 -> 0 | Y18: =+SUM(L18:V18) -> 450 | Z18: =+AA18+Y18 -> 1851 | AA18: 1401 | AE18: =+AD18*60 -> 0
B19: 4 | C19: 064-22 | E19: Stear | F19: 8035-888-800 | G19: 6600 | H19: Veste | I19: 51.08 | J19: 55 | K19: Sortie Chaine | L19: 55 | M19: 49 | N19: 55 | O19: 60 | P19: 56 | Q19: 55 | R19: 55 | S19: 55 | W19: =+IF(COUNTA(L19:V19)=0,0,Y19/(COUNTA(L19:V19))) -> 55 | Y19: =+SUM(L19:V19) -> 440 | Z19: =+Y19+AA19 -> 1095 | AA19: 655 | AB19: =+Z18-Z19 -> 756 | AC19: =+IF(((Y20+(Y21/2))*60)=0,"",(I19*Y19)/((Y20+(Y21/2))*60)) -> 0.88554768 | AE19: =+AD19*60 -> 0 | AF19: =+Y19*I19 -> 22475.2
B20: =+B19 -> 4 | C20: HAMID | D20: =+B19 -> 4 | F20: =+VLOOKUP(F19,'Obj Prix'!$H:$H,2,FALSE) -> #N/A | J20: EFF | K20: Effectifs | L20: 51 | M20: 52 | N20: 52 | O20: 52 | P20: 52 | Q20: 52 | R20: 52 | S20: 52 | W20: =+W19-J19 -> 0 | Y20: =+SUM(L20:V20) -> 415 | AE20: =+AD20*60 -> 0
B21: =+B19 -> 4 | D21: =+D20+100 -> 104 | F21: TOURABI | I21: =+IF(J21="","",IF(J19=0,"",(J19*I19)/(J21*60))) -> 0.90044872 | J21: 52 | K21: Stagiaire | L21: 2 | M21: 2 | N21: 2 | O21: 2 | P21: 2 | Q21: 2 | R21: 2 | S21: 2 | X21: 4.54 | Y21: =+SUM(L21:V21) -> 16 | AB21: =+IFERROR(AB19/(J19*9),"") -> 1.5272727 | AD21: =+Y20+Y21/2 -> 423 | AE21: =+AD21*60 -> 25380 | AG21: =+IF((Y19-J19*9)>=0,"",Y19-J19*9) -> -55
B22: =+B23 -> 5 | I22: VT | J22: P/H | K22: Entre Chaine | L22: 70 | M22: 70 | N22: 70 | O22: 70 | P22: 70 | Q22: 70 | X22: =+W24 -> 1.5 | Y22: =+SUM(L22:V22) -> 420 | Z22: =+AA22+Y22 -> 6301 | AA22: 5881 | AE22: =+AD22*60 -> 0
B23: 5 | C23: 040-22 | E23: Stear | F23: 7560-939-620 | G23: 12500 | H23: Veste | I23: 52.3 | J23: 55 | K23: Sortie Chaine | L23: 58 | M23: 51 | N23: 56 | O23: 55 | P23: 55 | Q23: 55 | R23: 66 | S23: 56 | W23: =+IF(COUNTA(L23:V23)=0,0,Y23/(COUNTA(L23:V23))) -> 56.5 | Y23: =+SUM(L23:V23) -> 452 | Z23: =+Y23+AA23 -> 5476 | AA23: 5024 | AB23: =+Z22-Z23 -> 825 | AC23: =+IF(((Y24+(Y25/2))*60)=0,"",(I23*Y23)/((Y24+(Y25/2))*60)) -> 0.90365443 | AE23: =+AD23*60 -> 0 | AF23: =+Y23*I23 -> 23639.6
B24: =+B23 -> 5 | D24: =+B23 -> 5 | F24: =+VLOOKUP(F23,'Obj Prix'!$H:$H,2,FALSE) -> #N/A | I24: 2 | J24: EFF | K24: Effectifs | L24: 54 | M24: 54 | N24: 54 | O24: 54 | P24: 54 | Q24: 54 | R24: 54 | S24: 54 | W24: =+W23-J23 -> 1.5 | Y24: =+SUM(L24:V24) -> 432 | AE24: =+AD24*60 -> 0
B25: =+B23 -> 5 | C25: MOHAMMED | D25: =+D24+100 -> 105 | F25: REDOUANE | I25: =+IF(J25="","",IF(J23=0,"",(J23*I23)/(J25*60))) -> 0.92195513 | J25: 52 | K25: Stagiaire | L25: 1 | M25: 1 | N25: 1 | O25: 1 | P25: 1 | Q25: 1 | R25: 1 | S25: 1 | X25: 9.64 | Y25: =+SUM(L25:V25) -> 8 | AB25: =+IFERROR(AB23/(J23*9),"") -> 1.6666667 | AD25: =+Y24+Y25/2 -> 436 | AE25: =+AD25*60 -> 26160 | AG25: =+IF((Y23-J23*9)>=0,"",Y23-J23*9) -> -43
B26: =+B27 -> 6 | I26: VT | J26: P/H | K26: Entre Chaine | X26: =+W28 -> -27.5 | Y26: =+SUM(L26:V26) -> 0 | Z26: =+AA26+Y26 -> 1826 | AA26: 1826 | AE26: =+AD26*60 -> 0
B27: 6 | C27: 047-22 | E27: sweet | F27: 221403013 | H27: TOP | I27: 22.45 | J27: 60 | K27: Sortie Chaine | L27: 30 | M27: 30 | N27: 30 | O27: 30 | P27: 35 | Q27: 35 | R27: 35 | S27: 35 | W27: =+IF(COUNTA(L27:V27)=0,0,Y27/(COUNTA(L27:V27))) -> 32.5 | Y27: =+SUM(L27:V27) -> 260 | Z27: =+Y27+AA27 -> 315 | AA27: 55 | AB27: =+Z26-Z27 -> 1511 | AC27: =+IF(((Y28+(Y29/2))*60)=0,"",(I27*Y27)/((Y28+(Y29/2))*60)) -> 0.50668403 | AE27: =+AD27*60 -> 0 | AF27: =+Y27*I27 -> 5837
B28: =+B27 -> 6 | D28: =+B27 -> 6 | F28: =+VLOOKUP(F27,'Obj Prix'!$H:$H,2,FALSE) -> #N/A | J28: EFF | K28: Effectifs | L28: 22 | M28: 22 | N28: 22 | O28: 22 | P28: 22 | Q28: 22 | R28: 22 | S28: 22 | W28: =+W27-J27 -> -27.5 | Y28: =+SUM(L28:V28) -> 176 | AE28: =+AD28*60 -> 0
B29: =+B27 -> 6 | C29: BACHIR | D29: =+D28+100 -> 106 | F29: REDOUANE | I29: =+IF(J29="","",IF(J27=0,"",(J27*I27)/(J29*60))) -> 0.86346154 | J29: 26 | K29: Stagiaire | L29: 4 | M29: 4 | N29: 4 | O29: 4 | P29: 4 | Q29: 4 | R29: 4 | S29: 4 | X29: =14.33+(COUNTA(L27:V27)-(Y27/J27)) -> 17.996667 | Y29: =+SUM(L29:V29) -> 32 | AB29: =+IFERROR(AB27/(J27*9),"") -> 2.7981481 | AD29: =+Y28+Y29/2 -> 192 | AE29: =+AD29*60 -> 11520 | AG29: =+IF((Y27-J27*9)>=0,"",Y27-J27*9) -> -280
B30: =+B31 -> 6 | I30: VT | J30: P/H | K30: Entre Chaine | X30: =+W32 -> 0 | Y30: =+SUM(L30:V30) -> 0 | Z30: =+AA30+Y30 -> 0 | AE30: =+AD30*60 -> 0
B31: 6 | C31: 052-22 | E31: sweet | F31: 221405021 | H31: Chemise | K31: Sortie Chaine | W31: =+IF(COUNTA(L31:V31)=0,0,Y31/(COUNTA(L31:V31))) -> 0 | Y31: =+SUM(L31:V31) -> 0 | Z31: =+Y31+AA31 -> 0 | AB31: =+Z30-Z31 -> 0 | AC31: =+IF(((Y32+(Y33/2))*60)=0,"",(I31*Y31)/((Y32+(Y33/2))*60)) | AE31: =+AD31*60 -> 0 | AF31: =+Y31*I31 -> 0
B32: =+B31 -> 6 | D32: =+B31 -> 6 | F32: =+VLOOKUP(F31,'Obj Prix'!$H:$H,2,FALSE) -> #N/A | J32: EFF | K32: Effectifs | W32: =+W31-J31 -> 0 | Y32: =+SUM(L32:V32) -> 0 | AE32: =+AD32*60 -> 0
B33: =+B31 -> 6 | C33: BACHIR | D33: =+D32+100 -> 106 | F33: REDOUANE | I33: =+IF(J33="","",IF(J31=0,"",(J31*I31)/(J33*60))) | J33: 23 | K33: Stagiaire | Y33: =+SUM(L33:V33) -> 0 | AB33: =+IFERROR(AB31/(J31*9),"") | AD33: =+Y32+Y33/2 -> 0 | AE33: =+AD33*60 -> 0 | AG33: =+IF((Y31-J31*9)>=0,"",Y31-J31*9)
B34: =+B35 -> 7 | I34: VT | J34: P/H | K34: Entre Chaine | L34: 100 | M34: 50 | N34: 50 | O34: 100 | P34: 50 | Q34: 100 | R34: 50 | X34: =+W36 -> 2 | Y34: =+SUM(L34:V34) -> 500 | Z34: =+AA34+Y34 -> 3826 | AA34: 3326 | AE34: =+AD34*60 -> 0
B35: 7 | C35: 064-22 | E35: Stear | F35: 8035-888-800 | G35: 6600 | H35: Veste | I35: 51.08 | J35: 55 | K35: Sortie Chaine | L35: 57 | M35: 57 | N35: 57 | O35: 57 | P35: 57 | Q35: 57 | R35: 57 | S35: 57 | W35: =+IF(COUNTA(L35:V35)=0,0,Y35/(COUNTA(L35:V35))) -> 57 | Y35: =+SUM(L35:V35) -> 456 | Z35: =+Y35+AA35 -> 3073 | AA35: 2617 | AB35: =+Z34-Z35 -> 753 | AC35: =+IF(((Y36+(Y37/2))*60)=0,"",(I35*Y35)/((Y36+(Y37/2))*60)) -> 0.93319231 | AE35: =+AD35*60 -> 0 | AF35: =+Y35*I35 -> 23292.48
B36: =+B35 -> 7 | D36: =+B35 -> 7 | F36: =+VLOOKUP(F35,'Obj Prix'!$H:$H,2,FALSE) -> #N/A | I36: 2 | J36: EFF | K36: Effectifs | L36: 51 | M36: 51 | N36: 51 | O36: 51 | P36: 51 | Q36: 51 | R36: 51 | S36: 51 | W36: =+W35-J35 -> 2 | Y36: =+SUM(L36:V36) -> 408 | AE36: =+AD36*60 -> 0
B37: =+B35 -> 7 | C37: YOUSSEF | D37: =+D36+100 -> 107 | F37: TOURABI | I37: =+IF(J37="","",IF(J35=0,"",(J35*I35)/(J37*60))) -> 0.90044872 | J37: 52 | K37: Stagiaire | L37: 2 | M37: 2 | N37: 2 | O37: 2 | P37: 2 | Q37: 2 | R37: 2 | S37: 2 | X37: 4.95 | Y37: =+SUM(L37:V37) -> 16 | AB37: =+IFERROR(AB35/(J35*9),"") -> 1.5212121 | AD37: =+Y36+Y37/2 -> 416 | AE37: =+AD37*60 -> 24960 | AG37: =+IF((Y35-J35*9)>=0,"",Y35-J35*9) -> -39
B38: =+B39 -> 8 | I38: VT | J38: P/H | K38: Entre Chaine | X38: =+W40 -> 3 | Y38: =+SUM(L38:V38) -> 0 | Z38: =+AA38+Y38 -> 6320 | AA38: 6320 | AE38: =+AD38*60 -> 0
B39: 8 | C39: 067-22 | E39: Stear | F39: 3013-888-251 | G39: 5500 | H39: SHORT | I39: 28.04 | J39: 107 | K39: Sortie Chaine | L39: 110 | M39: 110 | N39: 110 | O39: 110 | P39: 110 | Q39: 110 | R39: 110 | S39: 110 | W39: =+IF(COUNTA(L39:V39)=0,0,Y39/(COUNTA(L39:V39))) -> 110 | Y39: =+SUM(L39:V39) -> 880 | Z39: =+Y39+AA39 -> 5164 | AA39: 4284 | AB39: =+Z38-Z39 -> 1156 | AC39: =+IF(((Y40+(Y41/2))*60)=0,"",(I39*Y39)/((Y40+(Y41/2))*60)) -> 0.92624625 | AE39: =+AD39*60 -> 0 | AF39: =+Y39*I39 -> 24675.2
B40: =+B39 -> 8 | D40: =+B39 -> 8 | F40: =+VLOOKUP(F39,'Obj Prix'!$H:$H,2,FALSE) -> #N/A | I40: 1 | J40: EFF | K40: Effectifs | L40: 55 | M40: 55 | N40: 55 | O40: 55 | P40: 54 | Q40: 54 | R40: 54 | S40: 54 | W40: =+W39-J39 -> 3 | Y40: =+SUM(L40:V40) -> 436 | AE40: =+AD40*60 -> 0
...

Sheet 13-08-2022 (2)
B1: LA FICHE DE PRODUCTION DES CHAÎNES E06.03C | AB1: EXL 009-20
A2: 77 | AB2: =+AF2/AE2 -> 0.84402421 | AD2: 45 | AE2: =+SUBTOTAL(9,AE6:AE99) -> 382942.5 | AF2: =+SUBTOTAL(9,AF6:AF99) -> 323212.74
J3: HEURES SAISIE | L3: 6:45 | M3: 8:05 | N3: 9:05 | O3: 10:05 | P3: 11:20 | Q3: 12:20 | R3: 13:20 | S3: 14:20 | T3: 15:30 | AD3: 35 | AG3: 15
B4: CODERSA S.A.R.L. | J4: Fin Heure | L4: 6:45 | M4: 7:45 | N4: 8:45 | O4: 9:45 | P4: 11:00 | Q4: 12:00 | R4: 13:00 | S4: 14:00 | T4: 15:00 | U4: Arrêt Chaudière 45min | Y4: =+X83 -> 4927 | Z4: DATE : | AB4: 44786 | AD4: =+SUM(AD6:AD87) -> 6338.5 | AE4: =+SUM(AE6:AE87) -> 382942.5 | AF4: =+SUM(AF6:AF87) -> 323212.74 | AG4: =+SUM(AG6:AG87) -> 6213.625
B5: CH | C5: IMPORT | E5: CLIENT | F5: MODELE | G5: QTE PREVU | H5: DESIG | I5: METHODES | L5: 1 | M5: 2 | N5: 3 | O5: 4 | P5: 5 | Q5: 6 | R5: 7 | S5: 8 | T5: 9 | U5: 10 | V5: 11 | W5: Moy | X5: H.Lancement | Y5: Total | Z5: Cumul | AB5: Encours
B6: =+B7 -> 1 | I6: VT | J6: P/H | K6: Entre Chaine | L6: 50 | M6: 50 | N6: 50 | X6: =+W8 -> -2.3333333 | Y6: =+SUM(L6:V6) -> 150 | Z6: =+AA6+Y6 -> 2450 | AA6: 2300
B7: 1 | C7: 106-22 | E7: ZARA-MAT | F7: 340-350-401 | G7: 3000 | I7: 75.47 | J7: 37 | K7: Sortie Chaine | L7: 37 | M7: 37 | N7: 37 | O7: 37 | P7: 37 | Q7: 37 | R7: 19 | S7: 19 | W7: =+IF(COUNTA(L7:V7)=8,Y7/(COUNTA(L7:V7)-0.5),IF(COUNTA(L7:V7)=0,0,Y7/COUNTA(L7:V7))) -> 34.666667 | Y7: =+SUM(L7:V7) -> 260 | Z7: =+Y7+AA7 -> 2000 | AA7: 1740 | AB7: =+Z6-Z7 -> 450 | AC7: =+IF(((Y8+(Y9/2))*60)=0,"",(I7*Y7)/((Y8+(Y9/2))*60)) -> 0.74538272 | AF7: =+Y7*I7 -> 19622.2
B8: =B7 -> 1 | D8: =+B7 -> 1 | F8: =+VLOOKUP(F7,'Obj Prix'!$H:$H,2,FALSE) -> #N/A | I8: 2 | J8: EFF | K8: Effectifs | L8: 58 | M8: 58 | N8: 58 | O8: 58 | P8: 58 | Q8: 58 | R8: 58 | S8: 58 | W8: =+W7-J7 -> -2.3333333 | Y8: =+SUM(L8:V8)-S8/2 -> 435 | AD8: =-(R8+(R9/2))*$AD$2/60 -> -43.875
B9: =B7 -> 1 | C9: HICHAM | D9: =+D8+100 -> 101 | F9: AMINE | H9: 1 Spc + 1 PàM | I9: =+IF(J9="","",IF(J7=0,"",(J7*I7)/(J9*60))) -> 0.83106845 | J9: 56 | K9: Stagiaire | L9: 1 | M9: 1 | N9: 1 | O9: 1 | P9: 1 | Q9: 1 | R9: 1 | S9: 1 | X9: 17.19 | Y9: =+SUM(L9:V9)-S9/2 -> 7.5 | AB9: =+IFERROR(AB7/(J7*9),"") -> 1.3513514 | AD9: =+Y8+Y9/2 -> 438.75 | AE9: =+AD9*60 -> 26325 | AG9: =+AD8+AD9 -> 394.875
B10: =+B11 -> 2 | I10: VT | J10: P/H | K10: Entre Chaine | L10: 80 | M10: 80 | N10: 80 | P10: 40 | R10: 40 | X10: =+W12 -> -3.8666667 | Y10: =+SUM(L10:V10) -> 320 | Z10: =+AA10+Y10 -> 3040 | AA10: 2720 | AE10: =+AD10*60 -> 0
B11: 2 | C11: 127-22 | E11: Stear | F11: 8456-298-800 | G11: 8731 | H11: manteau | I11: 54.97 | J11: 50 | K11: Sortie Chaine | L11: 40 | M11: 50 | N11: 50 | O11: 45 | P11: 50 | Q11: 50 | R11: 36 | S11: 25 | W11: =+IF(COUNTA(L11:V11)=8,Y11/(COUNTA(L11:V11)-0.5),IF(COUNTA(L11:V11)=0,0,Y11/COUNTA(L11:V11))) -> 46.133333 | Y11: =+SUM(L11:V11) -> 346 | Z11: =+Y11+AA11 -> 2468 | AA11: 2122 | AB11: =+Z10-Z11 -> 572 | AC11: =+IF(((Y12+(Y13/2))*60)=0,"",(I11*Y11)/((Y12+(Y13/2))*60)) -> 0.82874161 | AE11: =+AD11*60 -> 0 | AF11: =+Y11*I11 -> 19019.62
B12: =+B11 -> 2 | D12: =+B11 -> 2 | F12: =+VLOOKUP(F11,'Obj Prix'!$H:$H,2,FALSE) -> #N/A | I12: 2 | J12: EFF | K12: Effectifs | L12: 50 | M12: 50 | N12: 50 | O12: 50 | P12: 50 | Q12: 50 | R12: 50 | S12: 50 | W12: =+W11-J11 -> -3.8666667 | Y12: =+SUM(L12:V12)-S12/2 -> 375 | AD12: =-(R12+(R13/2))*$AD$2/60 -> -38.25 | AE12: =+AD12*60 -> -2295
B13: =+B11 -> 2 | C13: ABDELWAHID | D13: =+D12+100 -> 102 | F13: REDOUANE | I13: =+IF(J13="","",IF(J11=0,"",(J11*I11)/(J13*60))) -> 0.88092949 | J13: 52 | K13: Stagiaire | L13: 2 | M13: 2 | N13: 2 | O13: 2 | P13: 2 | Q13: 2 | R13: 2 | S13: 2 | X13: =15.24+(COUNTA(L11:V11)-(Y11/J11)) -> 16.32 | Y13: =+SUM(L13:V13)-S13/2 -> 15 | AB13: =+IFERROR(AB11/(J11*9),"") -> 1.2711111 | AD13: =+Y12+Y13/2 -> 382.5 | AE13: =+AD13*60 -> 22950 | AG13: =+AD12+AD13 -> 344.25
B14: =+B15 -> 3 | I14: VT | J14: P/H | K14: Entre Chaine | L14: 100 | M14: 50 | N14: 50 | P14: 50 | Q14: 50 | X14: =+W16 -> -0.93333333 | Y14: =+SUM(L14:V14) -> 300 | Z14: =+AA14+Y14 -> 2350 | AA14: 2050 | AE14: =+AD14*60 -> 0 | AH14: 102-22 | AI14: 108-22
B15: 3 | C15: 123-22 | E15: Stear | F15: 8263-529-251 | G15: 3550 | H15: Veste | I15: 70.68 | J15: 44 | K15: Sortie Chaine | L15: 50 | M15: 50 | N15: 50 | O15: 45 | P15: 50 | Q15: 38 | R15: 20 | S15: 20 | W15: =+IF(COUNTA(L15:V15)=8,Y15/(COUNTA(L15:V15)-0.5),IF(COUNTA(L15:V15)=0,0,Y15/COUNTA(L15:V15))) -> 43.066667 | Y15: =+SUM(L15:V15) -> 323 | Z15: =+Y15+AA15 -> 1698 | AA15: 1375 | AB15: =+Z14-Z15 -> 652 | AC15: =+IF(((Y16+(Y17/2))*60)=0,"",(I15*Y15)/((Y16+(Y17/2))*60)) -> 0.85264762 | AE15: =+AD15*60 -> 0 | AF15: =+Y15*I15 -> 22829.64 | AH15: 1980 | AI15: 9732
B16: =+B15 -> 3 | D16: =+B15 -> 3 | F16: =+VLOOKUP(F15,'Obj Prix'!$H:$H,2,FALSE) -> #N/A | G16: A.FINAL | I16: 2 | J16: EFF | K16: Effectifs | L16: 57 | M16: 57 | N16: 57 | O16: 57 | P16: 57 | Q16: 57 | R16: 57 | S16: 57 | W16: =+W15-J15 -> -0.93333333 | Y16: =+SUM(L16:V16)-S16/2 -> 427.5 | AD16: =-(R16+(R17/2))*$AD$2/60 -> -44.625 | AE16: =+AD16*60 -> -2677.5
B17: =+B15 -> 3 | C17: SAID | D17: =+D16+100 -> 103 | F17: AMINE | H17: 2Spc+2PàM+4FL+Cont | I17: =+IF(J17="","",IF(J15=0,"",(J15*I15)/(J17*60))) -> 0.87850847 | J17: 59 | K17: Stagiaire | L17: 5 | M17: 5 | N17: 5 | O17: 5 | P17: 5 | Q17: 5 | R17: 5 | S17: 5 | X17: 17 | Y17: =+SUM(L17:V17)-S17/2 -> 37.5 | AB17: =+IFERROR(AB15/(J15*9),"") -> 1.6464646 | AD17: =+Y16+Y17/2 -> 446.25 | AE17: =+AD17*60 -> 26775 | AG17: =+AD16+AD17 -> 401.625
B18: =+B19 -> 4 | I18: VT | J18: P/H | K18: Entre Chaine | L18: 100 | M18: 100 | N18: 100 | X18: =+W20 -> 1 | Y18: =+SUM(L18:V18) -> 300 | Z18: =+AA18+Y18 -> 4201 | AA18: 3901 | AE18: =+AD18*60 -> 0
B19: 4 | C19: 118-22 | E19: Stear | F19: 7560-580-800 | G19: 11466 | H19: Veste | I19: 61.52 | J19: 45 | K19: Sortie Chaine | L19: 45 | M19: 45 | N19: 50 | O19: 50 | P19: 50 | Q19: 50 | R19: 30 | S19: 25 | W19: =+IF(COUNTA(L19:V19)=8,Y19/(COUNTA(L19:V19)-0.5),IF(COUNTA(L19:V19)=0,0,Y19/COUNTA(L19:V19))) -> 46 | Y19: =+SUM(L19:V19) -> 345 | Z19: =+Y19+AA19 -> 3382 | AA19: 3037 | AB19: =+Z18-Z19 -> 819 | AC19: =+IF(((Y20+(Y21/2))*60)=0,"",(I19*Y19)/((Y20+(Y21/2))*60)) -> 0.82746199 | AE19: =+AD19*60 -> 0 | AF19: =+Y19*I19 -> 21224.4
B20: =+B19 -> 4 | D20: =+B19 -> 4 | F20: =+VLOOKUP(F19,'Obj Prix'!$H:$H,2,FALSE) -> #N/A | G20: A.FINAL | I20: 1 | J20: EFF | K20: Effectifs | L20: 56 | M20: 56 | N20: 56 | O20: 56 | P20: 56 | Q20: 56 | R20: 56 | S20: 56 | W20: =+W19-J19 -> 1 | Y20: =+SUM(L20:V20)-S20/2 -> 420 | AD20: =-(R20+(R21/2))*$AD$2/60 -> -42.75 | AE20: =+AD20*60 -> -2565
B21: =+B19 -> 4 | C21: HAMID | D21: =+D20+100 -> 104 | F21: AMINE | H21: 2Pàm+4FL+Cont | I21: =+IF(J21="","",IF(J19=0,"",(J19*I19)/(J21*60))) -> 0.85444444 | J21: 54 | K21: Stagiaire | L21: 2 | M21: 2 | N21: 2 | O21: 2 | P21: 2 | Q21: 2 | R21: 2 | S21: 2 | X21: 27.11 | Y21: =+SUM(L21:V21)-S21/2 -> 15 | AB21: =+IFERROR(AB19/(J19*9),"") -> 2.0222222 | AD21: =+Y20+Y21/2 -> 427.5 | AE21: =+AD21*60 -> 25650 | AG21: =+AD20+AD21 -> 384.75
B22: =+B23 -> 5 | I22: VT | J22: P/H | K22: Entre Chaine | L22: 100 | M22: 100 | N22: 100 | P22: 73 | X22: =+W24 -> -3.4666667 | Y22: =+SUM(L22:V22) -> 373 | Z22: =+AA22+Y22 -> 2171 | AA22: 1798 | AE22: =+AD22*60 -> 0
B23: 5 | C23: 131-22 | E23: Stear | F23: 8482-321-401 | G23: 5000 | H23: Veste | I23: 66.74 | J23: 50 | K23: Sortie Chaine | L23: 50 | M23: 50 | N23: 50 | O23: 50 | P23: 50 | Q23: 40 | R23: 35 | S23: 24 | W23: =+IF(COUNTA(L23:V23)=8,Y23/(COUNTA(L23:V23)-0.5),IF(COUNTA(L23:V23)=0,0,Y23/COUNTA(L23:V23))) -> 46.533333 | Y23: =+SUM(L23:V23) -> 349 | Z23: =+Y23+AA23 -> 1301 | AA23: 952 | AB23: =+Z22-Z23 -> 870 | AC23: =+IF(((Y24+(Y25/2))*60)=0,"",(I23*Y23)/((Y24+(Y25/2))*60)) -> 0.8626763 | AE23: =+AD23*60 -> 0 | AF23: =+Y23*I23 -> 23292.26
B24: =+B23 -> 5 | D24: =+B23 -> 5 | F24: =+VLOOKUP(F23,'Obj Prix'!$H:$H,2,FALSE) -> #N/A | G24: A.FINAL | I24: 2 | J24: EFF | K24: Effectifs | L24: 59 | M24: 59 | N24: 59 | O24: 59 | P24: 59 | Q24: 59 | R24: 59 | S24: 59 | W24: =+W23-J23 -> -3.4666667 | Y24: =+SUM(L24:V24)-S24/2 -> 442.5 | AD24: =-(R24+(R25/2))*$AD$2/60 -> -45 | AE24: =+AD24*60 -> -2700
B25: =+B23 -> 5 | C25: MOHAMMED | D25: =+D24+100 -> 105 | F25: REDOUANE | H25: 2Pàm+4FL+Cont | I25: =+IF(J25="","",IF(J23=0,"",(J23*I23)/(J25*60))) -> 0.94265537 | J25: 59 | K25: Stagiaire | L25: 2 | M25: 2 | N25: 2 | O25: 2 | P25: 2 | Q25: 2 | R25: 2 | S25: 2 | X25: =16.85+(COUNTA(L23:V23)-(Y23/J23)) -> 17.87 | Y25: =+SUM(L25:V25)-S25/2 -> 15 | AB25: =+IFERROR(AB23/(J23*9),"") -> 1.9333333 | AD25: =+Y24+Y25/2 -> 450 | AE25: =+AD25*60 -> 27000 | AG25: =+AD24+AD25 -> 405
B26: =+B27 -> 6 | I26: VT | J26: P/H | K26: Entre Chaine | L26: 40 | M26: 40 | N26: 40 | O26: 40 | P26: 40 | Q26: 40 | R26: 40 | S26: 40 | X26: =+W28 -> -19.6 | Y26: =+SUM(L26:V26) -> 320 | Z26: =+AA26+Y26 -> 2400 | AA26: 2080 | AE26: =+AD26*60 -> 0
B27: 6 | C27: 127-22 | E27: Stear | F27: 8456-298-800 | G27: 8731 | H27: manteau | I27: 60.17 | J27: 50 | K27: Sortie Chaine | L27: 20 | M27: 24 | N27: 20 | O27: 40 | P27: 40 | Q27: 24 | R27: 40 | S27: 20 | W27: =+IF(COUNTA(L27:V27)=8,Y27/(COUNTA(L27:V27)-0.5),IF(COUNTA(L27:V27)=0,0,Y27/COUNTA(L27:V27))) -> 30.4 | Y27: =+SUM(L27:V27) -> 228 | Z27: =+Y27+AA27 -> 1593 | AA27: 1365 | AB27: =+Z26-Z27 -> 807 | AC27: =+IF(((Y28+(Y29/2))*60)=0,"",(I27*Y27)/((Y28+(Y29/2))*60)) -> 0.60368581 | AE27: =+AD27*60 -> 0 | AF27: =+Y27*I27 -> 13718.76
B28: =+B27 -> 6 | D28: =+B27 -> 6 | F28: =+VLOOKUP(F27,'Obj Prix'!$H:$H,2,FALSE) -> #N/A | G28: A.FINAL | I28: 2 | J28: EFF | K28: Effectifs | L28: 48 | M28: 48 | N28: 48 | O28: 48 | P28: 48 | Q28: 48 | R28: 48 | S28: 48 | W28: =+W27-J27 -> -19.6 | Y28: =+SUM(L28:V28)-S28/2 -> 360 | AD28: =-(R28+(R29/2))*$AD$2/60 -> -37.875 | AE28: =+AD28*60 -> -2272.5
B29: =+B27 -> 6 | C29: KAMAL | D29: =+D28+100 -> 106 | F29: REDOUANE | H29: 4FL+Cont | I29: =+IF(J29="","",IF(J27=0,"",(J27*I27)/(J29*60))) -> 0.8953869 | J29: 56 | K29: Stagiaire | L29: 5 | M29: 5 | N29: 5 | O29: 5 | P29: 5 | Q29: 5 | R29: 5 | S29: 5 | X29: =36.96+(COUNTA(L27:V27)-(Y27/J27)) -> 40.4 | Y29: =+SUM(L29:V29)-S29/2 -> 37.5 | AB29: =+IFERROR(AB27/(J27*9),"") -> 1.7933333 | AD29: =+Y28+Y29/2 -> 378.75 | AE29: =+AD29*60 -> 22725 | AG29: =+AD28+AD29 -> 340.875
B30: =+B31 -> 7 | I30: VT | J30: P/H | K30: Entre Chaine | X30: =+W32 -> -4 | Y30: =+SUM(L30:V30) -> 0 | Z30: =+AA30+Y30 -> 2950 | AA30: 2950 | AE30: =+AD30*60 -> 0 | AH30: 102-22 | AI30: 108-22
B31: 7 | C31: 123-22 | E31: Stear | F31: 8263-529-251 | G31: 2950 | H31: Veste | I31: 70.68 | J31: 44 | K31: Sortie Chaine | L31: 35 | M31: 45 | N31: 50 | O31: 60 | P31: 40 | Q31: 20 | R31: 30 | S31: 20 | W31: =+IF(COUNTA(L31:V31)=8,Y31/(COUNTA(L31:V31)-0.5),IF(COUNTA(L31:V31)=0,0,Y31/COUNTA(L31:V31))) -> 40 | Y31: =+SUM(L31:V31) -> 300 | Z31: =+Y31+AA31 -> 2922 | AA31: 2622 | AB31: =+Z30-Z31 -> 28 | AC31: =+IF(((Y32+(Y33/2))*60)=0,"",(I31*Y31)/((Y32+(Y33/2))*60)) -> 0.80272572 | AE31: =+AD31*60 -> 0 | AF31: =+Y31*I31 -> 21204 | AH31: 3448 | AI31: 8448
B32: =+B31 -> 7 | D32: =+B31 -> 7 | F32: =+VLOOKUP(F31,'Obj Prix'!$H:$H,2,FALSE) -> #N/A | G32: A.FINAL | I32: 3 | J32: EFF | K32: Effectifs | L32: 52 | M32: 58 | N32: 58 | O32: 58 | P32: 58 | Q32: 58 | R32: 58 | S32: 58 | W32: =+W31-J31 -> -4 | Y32: =+SUM(L32:V32)-S32/2 -> 429 | AD32: =-(R32+(R33/2))*$AD$2/60 -> -44.625 | AE32: =+AD32*60 -> -2677.5
B33: =+B31 -> 7 | C33: YOUSSEF | D33: =+D32+100 -> 107 | F33: AMINE | H33: 2Spc+2PàM+4FL+Cont | I33: =+IF(J33="","",IF(J31=0,"",(J31*I31)/(J33*60))) -> 0.89365517 | J33: 58 | K33: Stagiaire | L33: 3 | M33: 3 | N33: 3 | O33: 3 | P33: 3 | Q33: 3 | R33: 3 | S33: 3 | X33: 18.92 | Y33: =+SUM(L33:V33)-S33/2 -> 22.5 | AB33: =+IFERROR(AB31/(J31*9),"") -> 0.070707071 | AD33: =+Y32+Y33/2 -> 440.25 | AE33: =+AD33*60 -> 26415 | AG33: =+AD32+AD33 -> 395.625
B34: =+B35 -> 7 | I34: VT | J34: P/H | K34: Entre Chaine | M34: 50 | O34: 50 | P34: 50 | R34: 50 | X34: =+W36 -> -44 | Y34: =+SUM(L34:V34) -> 200 | Z34: =+AA34+Y34 -> 300 | AA34: 100 | AE34: =+AD34*60 -> 0 | AH34: 102-22 | AI34: 108-22
B35: 7 | C35: 122-22 | E35: Stear | F35: 8263-646-500 | G35: 16000 | H35: Veste | I35: 70.68 | J35: 44 | K35: Sortie Chaine | W35: =+IF(COUNTA(L35:V35)=8,Y35/(COUNTA(L35:V35)-0.5),IF(COUNTA(L35:V35)=0,0,Y35/COUNTA(L35:V35))) -> 0 | Y35: =+SUM(L35:V35) -> 0 | Z35: =+Y35+AA35 -> 0 | AA35: 0 | AB35: =+Z34-Z35 -> 300 | AC35: =+IF(((Y36+(Y37/2))*60)=0,"",(I35*Y35)/((Y36+(Y37/2))*60)) | AE35: =+AD35*60 -> 0 | AF35: =+Y35*I35 -> 0 | AH35: 3448 | AI35: 8448
B36: =+B35 -> 7 | D36: =+B35 -> 7 | F36: =+VLOOKUP(F35,'Obj Prix'!$H:$H,2,FALSE) -> #N/A | J36: EFF | K36: Effectifs | W36: =+W35-J35 -> -44 | Y36: =+SUM(L36:V36)-S36/2 -> 0 | AD36: =-(R36+(R37/2))*$AD$2/60 -> 0 | AE36: =+AD36*60 -> 0
B37: =+B35 -> 7 | C37: YOUSSEF | D37: =+D36+100 -> 107 | F37: AMINE | I37: =+IF(J37="","",IF(J35=0,"",(J35*I35)/(J37*60))) -> 0.89365517 | J37: 58 | K37: Stagiaire | Y37: =+SUM(L37:V37)-S37/2 -> 0 | AB37: =+IFERROR(AB35/(J35*9),"") -> 0.75757576 | AD37: =+Y36+Y37/2 -> 0 | AE37: =+AD37*60 -> 0
B38: =+B39 -> 8 | I38: VT | J38: P/H | K38: Entre Chaine | L38: 40 | M38: 40 | N38: 40 | O38: 40 | P38: 40 | Q38: 40 | R38: 40 | S38: 40 | X38: =+W40 -> -50 | Y38: =+SUM(L38:V38) -> 320 | Z38: =+AA38+Y38 -> 760 | AA38: 440 | AE38: =+AD38*60 -> 0
B39: 8 | C39: 127-22 | E39: Stear | F39: 8456-298-800 | G39: 8731 | H39: manteau | I39: 60.17 | J39: 50 | K39: Sortie Chaine | L39: 0 | M39: 0 | N39: 0 | O39: 0 | P39: 0 | Q39: 0 | R39: 0 | S39: 0 | W39: =+IF(COUNTA(L39:V39)=8,Y39/(COUNTA(L39:V39)-0.5),IF(COUNTA(L39:V39)=0,0,Y39/COUNTA(L39:V39))) -> 0 | Y39: =+SUM(L39:V39) -> 0 | Z39: =+Y39+AA39 -> 0 | AA39: 0 | AB39: =+Z38-Z39 -> 760 | AC39: =+IF(((Y40+(Y41/2))*60)=0,"",(I39*Y39)/((Y40+(Y41/2))*60)) -> 0 | AE39: =+AD39*60 -> 0 | AF39: =+Y39*I39 -> 0
B40: =+B39 -> 8 | D40: =+B39 -> 8 | F40: =+VLOOKUP(F39,'Obj Prix'!$H:$H,2,FALSE) -> #N/A | J40: EFF | K40: Effectifs | L40: 36 | M40: 36 | N40: 36 | O40: 36 | P40: 36 | Q40: 36 | R40: 36 | S40: 36 | W40: =+W39-J39 -> -50 | Y40: =+SUM(L40:V40)-S40/2 -> 270 | AD40: =-(R40+(R41/2))*$AD$2/60 -> -27.75 | AE40: =+AD40*60 -> -1665
...

Sheet 23-08-2022 (2)
B1: LA FICHE DE PRODUCTION DES CHAÎNES E06.03C | AB1: EXL 009-20
A2: 77 | AB2: =+AF2/AE2 -> 0.80229623 | AD2: 15 | AE2: =+SUBTOTAL(9,AE6:AE107) -> 504570 | AF2: =+SUBTOTAL(9,AF6:AF107) -> 404814.61
J3: HEURES SAISIE | L3: 6:45 | M3: 8:05 | N3: 9:05 | O3: 10:05 | P3: 11:20 | Q3: 12:20 | R3: 13:20 | S3: 14:20 | T3: 15:30
B4: CODERSA S.A.R.L. | J4: Fin Heure | L4: 6:45 | M4: 7:45 | N4: 8:45 | O4: 9:45 | P4: 11:00 | Q4: 12:00 | R4: 13:00 | S4: 14:00 | T4: 15:00 | Y4: =+X91 -> 6441 | Z4: DATE : | AB4: 44796 | AD4: =+SUM(AD6:AD95) -> 8409.5
B5: CH | C5: IMPORT | E5: CLIENT | F5: MODELE | G5: QTE PREVU | H5: DESIG | I5: METHODES | L5: 1 | M5: 2 | N5: 3 | O5: 4 | P5: 5 | Q5: 6 | R5: 7 | S5: 8 | T5: 9 | U5: 10 | V5: 11 | W5: Moy | X5: H.Lancement | Y5: Total | Z5: Cumul | AB5: Encours
B6: =+B7 -> 1 | I6: VT | J6: P/H | K6: Entre Chaine | L6: 50 | M6: 50 | N6: 50 | O6: 50 | P6: 50 | Q6: 50 | X6: =+W8 -> -26.888889 | Y6: =+SUM(L6:V6) -> 300 | Z6: =+AA6+Y6 -> 878 | AA6: 578
B7: 1 | C7: 129-22 | E7: Stear | F7: 8705-636-704 | G7: 10000 | H7: Veste | I7: 68.45 | J7: 50 | K7: Sortie Chaine | L7: 0 | M7: 18 | N7: 23 | O7: 22 | P7: 25 | Q7: 30 | R7: 30 | S7: 30 | T7: 30 | W7: =+IF(COUNTA(L7:V7)=0,0,Y7/(COUNTA(L7:V7))) -> 23.111111 | Y7: =+SUM(L7:V7) -> 208 | Z7: =+Y7+AA7 -> 208 | AA7: 0 | AB7: =+Z6-Z7 -> 670 | AC7: =+IF(((Y8+(Y9/2))*60)=0,"",(I7*Y7)/((Y8+(Y9/2))*60)) -> 0.43861984 | AF7: =+Y7*I7 -> 14237.6
B8: =B7 -> 1 | D8: =+B7 -> 1 | F8: =+VLOOKUP(F7,'Obj Prix'!$H:$H,2,FALSE) -> #N/A | J8: EFF | K8: Effectifs | L8: 54 | M8: 58 | N8: 60 | O8: 60 | P8: 60 | Q8: 60 | R8: 60 | S8: 60 | T8: 60 | W8: =+W7-J7 -> -26.888889 | Y8: =+SUM(L8:V8) -> 532 | AD8: =-(L8+(L9/2))*$AD$2/60 -> -13.75 | AE8: =+AD8*60 -> -825
B9: =B7 -> 1 | C9: HICHAM | D9: =+D8+100 -> 101 | F9: AMINE | I9: =+IF(J9="","",IF(J7=0,"",(J7*I7)/(J9*60))) -> 0.92002688 | J9: 62 | K9: Stagiaire | L9: 2 | M9: 2 | N9: 2 | O9: 2 | P9: 2 | Q9: 2 | R9: 2 | S9: 2 | T9: 2 | X9: =15.55+(COUNTA(L7:V7)-(Y7/J7)) -> 20.39 | Y9: =+SUM(L9:V9) -> 18 | AB9: =+IFERROR(AB7/(J7*9),"") -> 1.4888889 | AD9: =+Y8+Y9/2 -> 541 | AE9: =+AD9*60 -> 32460 | AG9: =+AD8+AD9 -> 527.25
B10: =+B11 -> 2 | I10: VT | J10: P/H | K10: Entre Chaine | L10: 80 | M10: 40 | N10: 80 | O10: 40 | P10: 40 | Q10: 40 | R10: 80 | S10: 40 | T10: 40 | X10: =+W12 -> 0.66666667 | Y10: =+SUM(L10:V10) -> 480 | Z10: =+AA10+Y10 -> 6040 | AA10: 5560 | AE10: =+AD10*60 -> 0
B11: 2 | C11: 127-22 | E11: Stear | F11: 8456-298-800 | G11: 8731 | H11: manteau | I11: 54.97 | J11: 50 | K11: Sortie Chaine | L11: 35 | M11: 52 | N11: 41 | O11: 52 | P11: 41 | Q11: 55 | R11: 55 | S11: 70 | T11: 55 | W11: =+IF(COUNTA(L11:V11)=0,0,Y11/(COUNTA(L11:V11))) -> 50.666667 | Y11: =+SUM(L11:V11) -> 456 | Z11: =+Y11+AA11 -> 5541 | AA11: 5085 | AB11: =+Z10-Z11 -> 499 | AC11: =+IF(((Y12+(Y13/2))*60)=0,"",(I11*Y11)/((Y12+(Y13/2))*60)) -> 0.96371857 | AE11: =+AD11*60 -> 0 | AF11: =+Y11*I11 -> 25066.32
B12: =+B11 -> 2 | D12: =+B11 -> 2 | F12: =+VLOOKUP(F11,'Obj Prix'!$H:$H,2,FALSE) -> #N/A | I12: 3 | J12: EFF | K12: Effectifs | L12: 45 | M12: 48 | N12: 48 | O12: 48 | P12: 48 | Q12: 48 | R12: 48 | S12: 48 | T12: 48 | W12: =+W11-J11 -> 0.66666667 | Y12: =+SUM(L12:V12) -> 429 | AD12: =-(L12+(L13/2))*$AD$2/60 -> -11.375 | AE12: =+AD12*60 -> -682.5
B13: =+B11 -> 2 | C13: ABDELWAHID | D13: =+D12+100 -> 102 | F13: REDOUANE | I13: =+IF(J13="","",IF(J11=0,"",(J11*I11)/(J13*60))) -> 0.88092949 | J13: 52 | K13: Stagiaire | L13: 1 | M13: 1 | N13: 1 | O13: 1 | P13: 1 | Q13: 1 | R13: 1 | S13: 1 | T13: 1 | X13: 18.18 | Y13: =+SUM(L13:V13) -> 9 | AB13: =+IFERROR(AB11/(J11*9),"") -> 1.1088889 | AD13: =+Y12+Y13/2 -> 433.5 | AE13: =+AD13*60 -> 26010 | AG13: =+AD12+AD13 -> 422.125
B14: =+B15 -> 3 | I14: VT | J14: P/H | K14: Entre Chaine | L14: 50 | M14: 50 | N14: 50 | O14: 50 | P14: 50 | Q14: 50 | R14: 50 | S14: 50 | T14: 50 | X14: =+W16 -> 0 | Y14: =+SUM(L14:V14) -> 450 | Z14: =+AA14+Y14 -> 1550 | AA14: 1100 | AE14: =+AD14*60 -> 0
B15: 3 | C15: 122-22 | E15: Stear | F15: 8263-646-500 | G15: 14500 | H15: Veste | I15: 70.68 | J15: 44 | K15: Sortie Chaine | L15: 20 | M15: 50 | N15: 50 | O15: 50 | P15: 50 | Q15: 50 | R15: 45 | S15: 45 | T15: 36 | W15: =+IF(COUNTA(L15:V15)=0,0,Y15/(COUNTA(L15:V15))) -> 44 | Y15: =+SUM(L15:V15) -> 396 | Z15: =+Y15+AA15 -> 800 | AA15: 404 | AB15: =+Z14-Z15 -> 750 | AC15: =+IF(((Y16+(Y17/2))*60)=0,"",(I15*Y15)/((Y16+(Y17/2))*60)) -> 0.84051892 | AE15: =+AD15*60 -> 0 | AF15: =+Y15*I15 -> 27989.28
B16: =+B15 -> 3 | D16: =+B15 -> 3 | F16: =+VLOOKUP(F15,'Obj Prix'!$H:$H,2,FALSE) -> #N/A | I16: 3 | J16: EFF | K16: Effectifs | L16: 56 | M16: 59 | N16: 59 | O16: 59 | P16: 59 | Q16: 59 | R16: 59 | S16: 59 | T16: 59 | W16: =+W15-J15 -> 0 | Y16: =+SUM(L16:V16) -> 528 | AD16: =-(L16+(L17/2))*$AD$2/60 -> -14.75 | AE16: =+AD16*60 -> -885
B17: =+B15 -> 3 | C17: SAID | D17: =+D16+100 -> 103 | F17: AMINE | I17: =+IF(J17="","",IF(J15=0,"",(J15*I15)/(J17*60))) -> 0.87850847 | J17: 59 | K17: Stagiaire | L17: 6 | M17: 6 | N17: 6 | O17: 6 | P17: 6 | Q17: 6 | R17: 6 | S17: 6 | T17: 6 | X17: 17 | Y17: =+SUM(L17:V17) -> 54 | AB17: =+IFERROR(AB15/(J15*9),"") -> 1.8939394 | AD17: =+Y16+Y17/2 -> 555 | AE17: =+AD17*60 -> 33300 | AG17: =+AD16+AD17 -> 540.25
B18: =+B19 -> 4 | I18: VT | J18: P/H | K18: Entre Chaine | L18: 100 | M18: 50 | N18: 50 | O18: 50 | P18: 50 | Q18: 50 | X18: =+W20 -> 0 | Y18: =+SUM(L18:V18) -> 350 | Z18: =+AA18+Y18 -> 7001 | AA18: 6651 | AE18: =+AD18*60 -> 0
B19: 4 | C19: 118-22 | E19: Stear | F19: 7560-580-800 | G19: 11466 | H19: Veste | I19: 61.52 | J19: 45 | K19: Sortie Chaine | L19: 25 | M19: 45 | N19: 45 | O19: 45 | P19: 45 | Q19: 45 | R19: 65 | S19: 45 | T19: 45 | W19: =+IF(COUNTA(L19:V19)=0,0,Y19/(COUNTA(L19:V19))) -> 45 | Y19: =+SUM(L19:V19) -> 405 | Z19: =+Y19+AA19 -> 6244 | AA19: 5839 | AB19: =+Z18-Z19 -> 757 | AC19: =+IF(((Y20+(Y21/2))*60)=0,"",(I19*Y19)/((Y20+(Y21/2))*60)) -> 0.78129821 | AE19: =+AD19*60 -> 0 | AF19: =+Y19*I19 -> 24915.6
B20: =+B19 -> 4 | D20: =+B19 -> 4 | F20: =+VLOOKUP(F19,'Obj Prix'!$H:$H,2,FALSE) -> #N/A | G20: A.FINAL | I20: 4 | J20: EFF | K20: Effectifs | L20: 54 | M20: 58 | N20: 58 | O20: 58 | P20: 58 | Q20: 58 | R20: 58 | S20: 58 | T20: 58 | W20: =+W19-J19 -> 0 | Y20: =+SUM(L20:V20) -> 518 | AD20: =-(L20+(L21/2))*$AD$2/60 -> -13.875 | AE20: =+AD20*60 -> -832.5
B21: =+B19 -> 4 | C21: HAMID | D21: =+D20+100 -> 104 | F21: AMINE | H21: 2Pàm+4FL+Cont | I21: =+IF(J21="","",IF(J19=0,"",(J19*I19)/(J21*60))) -> 0.85444444 | J21: 54 | K21: Stagiaire | L21: 3 | M21: 3 | N21: 3 | O21: 3 | P21: 3 | Q21: 3 | R21: 3 | S21: 3 | T21: 3 | X21: 27.11 | Y21: =+SUM(L21:V21) -> 27 | AB21: =+IFERROR(AB19/(J19*9),"") -> 1.8691358 | AD21: =+Y20+Y21/2 -> 531.5 | AE21: =+AD21*60 -> 31890 | AG21: =+AD20+AD21 -> 517.625
B22: =+B23 -> 5 | I22: VT | J22: P/H | K22: Entre Chaine | L22: 34 | M22: 19 | N22: 18 | X22: =+W24 -> -5.5555556 | Y22: =+SUM(L22:V22) -> 71 | Z22: =+AA22+Y22 -> 4806 | AA22: 4735 | AE22: =+AD22*60 -> 0
B23: 5 | C23: 131-22 | E23: Stear | F23: 8482-321-401 | G23: 5000 | H23: Veste | I23: 66.74 | J23: 50 | K23: Sortie Chaine | L23: 30 | M23: 50 | N23: 40 | O23: 50 | P23: 50 | Q23: 50 | R23: 50 | S23: 50 | T23: 30 | W23: =+IF(COUNTA(L23:V23)=0,0,Y23/(COUNTA(L23:V23))) -> 44.444444 | Y23: =+SUM(L23:V23) -> 400 | Z23: =+Y23+AA23 -> 4218 | AA23: 3818 | AB23: =+Z22-Z23 -> 588 | AC23: =+IF(((Y24+(Y25/2))*60)=0,"",(I23*Y23)/((Y24+(Y25/2))*60)) -> 0.82701363 | AE23: =+AD23*60 -> 0 | AF23: =+Y23*I23 -> 26696
B24: =+B23 -> 5 | D24: =+B23 -> 5 | F24: =+VLOOKUP(F23,'Obj Prix'!$H:$H,2,FALSE) -> #N/A | G24: A.FINAL | I24: 3 | J24: EFF | K24: Effectifs | L24: 56 | M24: 58 | N24: 58 | O24: 58 | P24: 58 | Q24: 58 | R24: 58 | S24: 58 | T24: 58 | W24: =+W23-J23 -> -5.5555556 | Y24: =+SUM(L24:V24) -> 520 | AD24: =-(L24+(L25/2))*$AD$2/60 -> -14.5 | AE24: =+AD24*60 -> -870
B25: =+B23 -> 5 | C25: MOHAMMED | D25: =+D24+100 -> 105 | F25: REDOUANE | H25: 2Pàm+4FL+Cont | I25: =+IF(J25="","",IF(J23=0,"",(J23*I23)/(J25*60))) -> 0.94265537 | J25: 59 | K25: Stagiaire | L25: 4 | M25: 4 | N25: 4 | O25: 4 | P25: 4 | Q25: 4 | R25: 4 | S25: 4 | T25: 4 | X25: 16.85 | Y25: =+SUM(L25:V25) -> 36 | AB25: =+IFERROR(AB23/(J23*9),"") -> 1.3066667 | AD25: =+Y24+Y25/2 -> 538 | AE25: =+AD25*60 -> 32280 | AG25: =+AD24+AD25 -> 523.5
B26: =+B27 -> 5 | I26: VT | J26: P/H | K26: Entre Chaine | O26: 40 | P26: 40 | Q26: 40 | R26: 40 | X26: =+W28 -> 0 | Y26: =+SUM(L26:V26) -> 160 | Z26: =+AA26+Y26 -> 160 | AE26: =+AD26*60 -> 0
B27: 5 | C27: 139-22 | E27: Stear | F27: 7553-457-630 | H27: Veste | K27: Sortie Chaine | W27: =+IF(COUNTA(L27:V27)=0,0,Y27/(COUNTA(L27:V27))) -> 0 | Y27: =+SUM(L27:V27) -> 0 | Z27: =+Y27+AA27 -> 0 | AB27: =+Z26-Z27 -> 160 | AC27: =+IF(((Y28+(Y29/2))*60)=0,"",(I27*Y27)/((Y28+(Y29/2))*60)) | AE27: =+AD27*60 -> 0 | AF27: =+Y27*I27 -> 0
B28: =+B27 -> 5 | D28: =+B27 -> 5 | F28: =+VLOOKUP(F27,'Obj Prix'!$H:$H,2,FALSE) -> #N/A | J28: EFF | K28: Effectifs | W28: =+W27-J27 -> 0 | Y28: =+SUM(L28:V28) -> 0 | AD28: =-(L28+(L29/2))*$AD$2/60 -> 0 | AE28: =+AD28*60 -> 0
B29: =+B27 -> 5 | C29: MOHAMMED | D29: =+D28+100 -> 105 | F29: REDOUANE | I29: =+IF(J29="","",IF(J27=0,"",(J27*I27)/(J29*60))) | K29: Stagiaire | Y29: =+SUM(L29:V29) -> 0 | AB29: =+IFERROR(AB27/(J27*9),"") | AD29: =+Y28+Y29/2 -> 0 | AE29: =+AD29*60 -> 0 | AG29: =+AD28+AD29 -> 0
B30: =+B31 -> 6 | I30: VT | J30: P/H | K30: Entre Chaine | L30: 40 | M30: 40 | N30: 40 | O30: 40 | P30: 40 | Q30: 40 | R30: 80 | S30: 40 | T30: 40 | X30: =+W32 -> -8.4444444 | Y30: =+SUM(L30:V30) -> 400 | Z30: =+AA30+Y30 -> 4680 | AA30: 4280 | AE30: =+AD30*60 -> 0
B31: 6 | C31: 127-22 | E31: Stear | F31: 8456-298-800 | G31: 8731 | H31: manteau | I31: 55.97 | J31: 50 | K31: Sortie Chaine | L31: 15 | M31: 30 | N31: 39 | O31: 45 | P31: 45 | Q31: 45 | R31: 65 | S31: 45 | T31: 45 | W31: =+IF(COUNTA(L31:V31)=0,0,Y31/(COUNTA(L31:V31))) -> 41.555556 | Y31: =+SUM(L31:V31) -> 374 | Z31: =+Y31+AA31 -> 4067 | AA31: 3693 | AB31: =+Z30-Z31 -> 613 | AC31: =+IF(((Y32+(Y33/2))*60)=0,"",(I31*Y31)/((Y32+(Y33/2))*60)) -> 0.77271244 | AE31: =+AD31*60 -> 0 | AF31: =+Y31*I31 -> 20932.78
B32: =+B31 -> 6 | D32: =+B31 -> 6 | F32: =+VLOOKUP(F31,'Obj Prix'!$H:$H,2,FALSE) -> #N/A | G32: A.FINAL | I32: 6 | J32: EFF | K32: Effectifs | L32: 48 | M32: 48 | N32: 48 | O32: 48 | P32: 48 | Q32: 48 | R32: 47 | S32: 47 | T32: 47 | W32: =+W31-J31 -> -8.4444444 | Y32: =+SUM(L32:V32) -> 429 | AD32: =-(L32+(L33/2))*$AD$2/60 -> -12.625 | AE32: =+AD32*60 -> -757.5
B33: =+B31 -> 6 | C33: OMAR | D33: =+D32+100 -> 106 | F33: TOURABI | H33: 2FL+Cont | I33: =+IF(J33="","",IF(J31=0,"",(J31*I31)/(J33*60))) -> 0.89695513 | J33: 52 | K33: Stagiaire | L33: 5 | M33: 5 | N33: 5 | O33: 5 | P33: 5 | Q33: 5 | R33: 5 | S33: 5 | T33: 5 | X33: =52.4+(COUNTA(L31:V31)-(Y31/J31)) -> 53.92 | Y33: =+SUM(L33:V33) -> 45 | AB33: =+IFERROR(AB31/(J31*9),"") -> 1.3622222 | AD33: =+Y32+Y33/2 -> 451.5 | AE33: =+AD33*60 -> 27090 | AG33: =+AD32+AD33 -> 438.875
B34: =+B35 -> 7 | I34: VT | J34: P/H | K34: Entre Chaine | L34: 120 | M34: 60 | N34: 60 | O34: 60 | P34: 60 | Q34: 60 | X34: =+W36 -> -22.222222 | Y34: =+SUM(L34:V34) -> 420 | Z34: =+AA34+Y34 -> 1030 | AA34: 610 | AE34: =+AD34*60 -> 0
B35: 7 | C35: 135-22 | E35: Stear | F35: 8880-888-942 | G35: 7720 | H35: Veste | I35: 62.08 | J35: 49 | K35: Sortie Chaine | L35: 11 | M35: 30 | N35: 69 | O35: 8 | P35: 16 | Q35: 30 | R35: 30 | S35: 27 | T35: 20 | W35: =+IF(COUNTA(L35:V35)=0,0,Y35/(COUNTA(L35:V35))) -> 26.777778 | Y35: =+SUM(L35:V35) -> 241 | Z35: =+Y35+AA35 -> 281 | AA35: 40 | AB35: =+Z34-Z35 -> 749 | AC35: =+IF(((Y36+(Y37/2))*60)=0,"",(I35*Y35)/((Y36+(Y37/2))*60)) -> 0.47723381 | AE35: =+AD35*60 -> 0 | AF35: =+Y35*I35 -> 14961.28
B36: =+B35 -> 7 | D36: =+B35 -> 7 | F36: =+VLOOKUP(F35,'Obj Prix'!$H:$H,2,FALSE) -> #N/A | G36: A.FINAL | I36: 3 | J36: EFF | K36: Effectifs | L36: 56 | M36: 57 | N36: 57 | O36: 57 | P36: 57 | Q36: 57 | R36: 56 | S36: 56 | T36: 56 | W36: =+W35-J35 -> -22.222222 | Y36: =+SUM(L36:V36) -> 509 | AD36: =-(L36+(L37/2))*$AD$2/60 -> -14.375 | AE36: =+AD36*60 -> -862.5
B37: =+B35 -> 7 | C37: YOUSSEF | D37: =+D36+100 -> 107 | F37: AMINE | H37: 2CON+ 4 fL | I37: =+IF(J37="","",IF(J35=0,"",(J35*I35)/(J37*60))) -> 0.88945029 | J37: 57 | K37: Stagiaire | L37: 3 | M37: 3 | N37: 3 | O37: 3 | P37: 3 | Q37: 3 | R37: 3 | S37: 3 | T37: 3 | X37: =13.3+(COUNTA(L35:V35)-(Y35/J35)) -> 17.381633 | Y37: =+SUM(L37:V37) -> 27 | AB37: =+IFERROR(AB35/(J35*9),"") -> 1.6984127 | AD37: =+Y36+Y37/2 -> 522.5 | AE37: =+AD37*60 -> 31350 | AG37: =+AD36+AD37 -> 508.125
B38: =+B39 -> 8 | I38: VT | J38: P/H | K38: Entre Chaine | L38: 40 | M38: 40 | N38: 40 | O38: 40 | P38: 80 | Q38: 40 | R38: 80 | S38: 40 | T38: 40 | X38: =+W40 -> 0.77777778 | Y38: =+SUM(L38:V38) -> 440 | Z38: =+AA38+Y38 -> 3000 | AA38: 2560 | AE38: =+AD38*60 -> 0
B39: 8 | C39: 127-22 | E39: Stear | F39: 8456-298-800 | G39: 8731 | H39: manteau | I39: 55.97 | J39: 50 | K39: Sortie Chaine | L39: 44 | M39: 56 | N39: 50 | O39: 50 | P39: 50 | Q39: 51 | R39: 52 | S39: 52 | T39: 52 | W39: =+IF(COUNTA(L39:V39)=0,0,Y39/(COUNTA(L39:V39))) -> 50.777778 | Y39: =+SUM(L39:V39) -> 457 | Z39: =+Y39+AA39 -> 2304 | AA39: 1847 | AB39: =+Z38-Z39 -> 696 | AC39: =+IF(((Y40+(Y41/2))*60)=0,"",(I39*Y39)/((Y40+(Y41/2))*60)) -> 0.87717044 | AE39: =+AD39*60 -> 0 | AF39: =+Y39*I39 -> 25578.29
B40: =+B39 -> 8 | D40: =+B39 -> 8 | F40: =+VLOOKUP(F39,'Obj Prix'!$H:$H,2,FALSE) -> #N/A | G40: A.FINAL | I40: 2 | J40: EFF | K40: Effectifs | L40: 52 | M40: 52 | N40: 52 | O40: 52 | P40: 52 | Q40: 52 | R40: 52 | S40: 52 | T40: 52 | W40: =+W39-J39 -> 0.77777778 | Y40: =+SUM(L40:V40) -> 468 | AD40: =-(L40+(L41/2))*$AD$2/60 -> -13.5 | AE40: =+AD40*60 -> -810
...

Sheet Garys
I1: 37
I2: =+SUBTOTAL(9,I6:I1000) -> 82329.369 | J2: =+SUBTOTAL(9,J6:J1000) -> 140309.54 | K2: =+I2/J2 -> 0.58676957
B4: Date | C4: Modèle | D4: Prix | E4: Moy effectif | F4: Heures Presence | G4: Production | I4: Charges | J4: Chiffre Affaire | K4: % | X4: Horaires | Y4: Mensuels
